Workbook

Sheet 数据统计
A1: 轻学堂内容数据统计
B2: 课程类型 | D2: 课程数量 | E2: 总集数 | F2: 集数占比 | G2: 总时长/h | H2: 时长占比 | I2: 原价/元
A3: 课程 | B3: 通用课 | D3: =COUNTIFS(通用课!C:C,"通用课") -> 332 | E3: =SUM(通用课!K3:K598) -> 41544 | F3: =E3/E9 -> 0.42216938 | G3: =SUM(通用课!L3:L498) -> 229578.49 | H3: =G3/G9 -> 0.69457652 | I3: =SUM(通用课!N3:N1048576) -> 37030.53
B4: 岗位课 | D4: =COUNTIF(岗位课!C:C,"岗位课") -> 231 | E4: =SUM(岗位课!K3:K469) -> 7874 | F4: =E4/E9 -> 0.080015446 | G4: =SUM(岗位课!L3:L499) -> 1600.69 | H4: =G4/G9 -> 0.0048427956 | I4: =SUM(岗位课!N2:N1048576) -> 35873.1
B5: 商学院 | D5: =COUNTIF(商学院!C3:C103,"商学院") -> 101 | E5: =SUM(商学院!K3:K200) -> 3658 | F5: =E5/E9 -> 0.03717253 | G5: =SUM(商学院!L3:L200) -> 90008.972 | H5: =G5/G9 -> 0.27231697 | I5: =SUM(商学院!N3:N1048576) -> 12871.49
B6: 其他 | D6: =COUNTIFS('课程列表（总）'!C3:C1028,"其他") -> 415 | E6: =SUMIFS('课程列表（总）'!M3:M1028,'课程列表（总）'!C3:C1028,"其他") -> 29646 | F6: =E6/E9 -> 0.30126212 | G6: =SUMIFS('课程列表（总）'!N3:N1028,'课程列表（总）'!C3:C1028,"其他") -> 4252.14 | H6: =G6/G9 -> 0.012864605 | I6: =SUMIFS('课程列表（总）'!P3:P1048576,'课程列表（总）'!C3:C1048576,"其他") -> 6472.7
A7: 书籍 | B7: 有声书 | D7: =COUNTIFS('书籍列表（总）'!B3:B1048576,"有声书") -> 352 | E7: =SUMIFS('书籍列表（总）'!H4:H1153,'书籍列表（总）'!B4:B1153,"有声书") -> 14456 | F7: =E7/E9 -> 0.14690161 | G7: =SUMIFS('书籍列表（总）'!I4:I1153,'书籍列表（总）'!B4:B1153,"讲书") -> 664.1505 | H7: =G7/G9 -> 0.0020093492 | I7: =SUMIFS('书籍列表（总）'!L4:L1048576,'书籍列表（总）'!B4:B1048576,"有声书") -> 10921.93
B8: 讲书 | D8: =COUNTIFS('书籍列表（总）'!B4:B1500,"讲书") -> 882 | E8: =SUMIFS('书籍列表（总）'!H4:H1153,'书籍列表（总）'!B4:B1153,"讲书") -> 1228 | F8: =E8/E9 -> 0.012478914 | G8: =SUMIFS('书籍列表（总）'!L4:L1048576,'书籍列表（总）'!B4:B1048576,"讲书") -> 4425.72 | H8: =G8/G9 -> 0.013389761 | I8: =SUMIFS('书籍列表（总）'!L4:L1048576,'书籍列表（总）'!B4:B1048576,"讲书") -> 4425.72
A9: 总计 | D9: =SUM(D3:D8) -> 2313 | E9: =SUM(E3:E8) -> 98406 | F9: / | G9: =SUM(G3:G8) -> 330530.16 | H9: / | I9: =ROUND(SUM(I3:I8),2)&"(会员畅听价399元/年/人)" -> 107595.47(会员畅听价399元/年/人)

Sheet 课程列表（总）
A1: 轻学堂—课程列表
A2: 内容说明： 1. VIP精品课，适用VIP用户企业，针对不同岗位和层级的能力提升需求，优选头部讲师和资源，打造最专业、权威、实战的课程； 2. 畅听课，适用所有企业，只要注册就可免费畅听，是轻学堂从喜马拉雅资源库引进的优质课程，致力服务更多企业。 3. 企业使用场景建议：挑选课程补充现有人才培养项目；挑选课单打造专题线上学习；挑选企业主推课程进行全员学习，营造学习氛围。
A3: 序号 | B3: 内容大类 | C3: 频道页 | D3: 一级标签 | E3: 二级标签 | F3: 课程名称 | G3: 副标题 | H3: 主讲人 | I3: 课程形式 | J3: 适用岗位 | K3: 适用职级 | L3: 轻学堂上架日期 | M3: 课程总课时/集 | N3: 已上架课时总时间/h | O3: 更新状态 | P3: 单卖价格/元
A4: =ROW()-3 -> 1 | B4: VIP精品课 | C4: 岗位课 | D4: 市场品牌 | E4: 营销思维 | F4: 叶茂中营销课堂：唤醒你的创意 | G4: 策划大师的私房课，向公众公开他营销与策划的法宝 | H4: 叶茂中 | I4: 音频 | J4: 全员 | K4: 基层管理者、中层管理者、职场新人 | L4: 43238 | M4: 72 | N4: 22.9 | O4: 已完结 | P4: 198
A5: =ROW()-3 -> 2 | B5: VIP精品课 | C5: 岗位课 | D5: 市场品牌 | E5: 营销思维 | F5: 林建红的定位营销课 | G5: 汲取商业的经典理论，掌握独创的系统方法论，打开商业和人生的崭新大门 | H5: 林建红 | I5: 音频 | J5: 销售、市场品牌 | K5: 中层管理者、专业人士 | L5: 43238 | M5: 31 | N5: 6.83 | O5: 已完结 | P5: 49.9
A6: =ROW()-3 -> 3 | B6: VIP精品课 | C6: 岗位课 | D6: 市场品牌 | E6: 营销策略 | F6: 李饷：趣读消费心理学 | G6: 有梗、有趣、有料，听着脱口秀，就能秒懂客户心理的消费心理学课程 | H6: 李饷 | I6: 音频 | J6: 销售 | K6: 中层管理者、专业人士 | L6: 43238 | M6: 39 | N6: 6.92 | O6: 已完结 | P6: 86
A7: =ROW()-3 -> 4 | B7: VIP精品课 | C7: 岗位课 | D7: 人力资源 | E7: 人力资源规划 | F7: Lisa的人力资源管理课 | G7: 不讲理论，只解决问题，教你从管人管事到管心，快速打造精英团队 | H7: Lisa | I7: 音频 | J7: CEO、管理者、HR | K7: 中层管理者、专业人士 | L7: 43238 | M7: 41 | N7: 7.65 | O7: 已完结 | P7: 129
A8: =ROW()-3 -> 5 | B8: VIP精品课 | C8: 岗位课 | D8: 销售 | E8: 销售技能 | F8: 倪建伟：销售如何搞定人 | G8: 帮助许多销售新手学到了受用一生的销售思维和技巧 | H8: 倪建伟 | I8: 音频 | J8: 销售 | K8: 中层管理者、专业人士 | L8: 43256 | M8: 67 | N8: 15.37 | O8: 已完结 | P8: 139
A9: =ROW()-3 -> 6 | B9: VIP精品课 | C9: 岗位课 | D9: 销售 | E9: 销售技能 | F9: 倪建伟：顶级销售成长课 | G9: 浓缩20年的大客户销售实战经验和多年的培训管理技巧 | H9: 倪建伟 | I9: 音频 | J9: 销售 | K9: 中层管理者、专业人士 | L9: 43256 | M9: 54 | N9: 12.9 | O9: 已完结 | P9: 139
A10: =ROW()-3 -> 7 | B10: VIP精品课 | C10: 岗位课 | D10: 市场品牌 | E10: 品牌管理 | F10: 李光斗品牌商学院:实战MBA品牌课 | G10: 破解商战背后的秘笈，启迪全新的商业机会，塑造独具竞争优势的盈利模式 | H10: 李光斗 | I10: 音频 | J10: 销售、市场品牌 | K10: 中层管理者、专业人士 | L10: 43262 | M10: 129 | N10: 21.19 | O10: 已完结 | P10: 365
A11: =ROW()-3 -> 8 | B11: VIP精品课 | C11: 岗位课 | D11: 金融理财 | E11: 金融知识与技能 | F11: 向松祚讲货币与金融 | G11: 货币是财富的载体，金融是时间的机器，看透货币本质，理解金融逻辑 | H11: 向松祚 | I11: 音频 | J11: CEO、管理者、财务 | K11: 中层管理者、高层管理者 | L11: 43293 | M11: 114 | N11: 19.71 | O11: 已完结 | P11: 199
A12: =ROW()-3 -> 9 | B12: VIP精品课 | C12: 岗位课 | D12: 人力资源 | E12: 劳动关系管理 | F12: 劳动法实操：企业用工风险防范指南 | G12: 劳动法实操：企业用工风险防范指南 | H12: 孔霞 | I12: 音频 | J12: 法务、HR | K12: 专业人士 | L12: 43321 | M12: 14 | N12: 2.88 | O12: 已完结 | P12: 99
A13: =ROW()-3 -> 10 | B13: VIP精品课 | C13: 岗位课 | D13: 市场品牌 | E13: 市场定位 | F13: 天猫创始总经理黄若的新零售课 | G13: 行业大咖30年的经验总结和100多个新鲜案例剖析，教你具体的商业策略与运营思路 | H13: 黄若 | I13: 音频 | J13: 销售、市场品牌 | K13: 中层管理者、专业人士 | L13: 43340 | M13: 50 | N13: 10.46 | O13: 已完结 | P13: 99
A14: =ROW()-3 -> 11 | B14: VIP精品课 | C14: 岗位课 | D14: 销售 | E14: 大客户销售 | F14: 觉伟讲销售：500强实战精华 | G14: 30年销售经验，6大模块倾力分享，帮助销售人员的个人成长，全面提升销售业绩 | H14: 李觉伟 | I14: 音频 | J14: 销售 | K14: 中层管理者、专业人士 | L14: 43346 | M14: 38 | N14: 7.5 | O14: 已完结 | P14: 199
A15: =ROW()-3 -> 12 | B15: VIP精品课 | C15: 岗位课 | D15: 市场品牌 | E15: 品牌管理 | F15: 品牌和营销：从入门到精通100讲 | G15: 营销=品牌思维+创造价值 | H15: 李婷 | I15: 音频 | J15: 销售、市场品牌 | K15: 中层管理者、专业人士 | L15: 43356 | M15: 100 | N15: 12.57 | O15: 已完结 | P15: 99
... A163: =ROW()-3 -> 160 | B163: VIP精品课 | C163: 岗位课 | D163: 金融理财 | E163: 证券 | F163: 高频交易15讲：探寻纳秒时代的金融市场 | G163: 新时代金融从业者的必修课 | H163: 李路 | I163: 音频 | J163: 管理者、财务 | K163: 专业人士 | L163: 44563 | M163: 17 | N163: 2.8 | O163: 已完结 | P163: 69
A164: =ROW()-3 -> 161 | B164: VIP精品课 | C164: 岗位课 | D164: 金融理财 | E164: 财富管理与资产配置 | F164: 投资理财必修的金融常识课 | G164: #NAME? | H164: 黎京林 | I164: 视频 | J164: 全员 | K164: 基层管理者、职场新人 | L164: 44563 | M164: 12 | N164: 2.3877778 | O164: 已完结 | P164: 39
A165: =ROW()-3 -> 162 | B165: VIP精品课 | C165: 岗位课 | D165: 金融理财 | E165: 财富管理与资产配置 | F165: 如何抓住潜伏的暴涨股 | G165: 识别被大家忽略的牛股 | H165: 闵遥 | I165: 视频 | J165: 全员 | K165: 基层管理者、职场新人 | L165: 44563 | M165: 16 | N165: 1.9572222 | O165: 已完结 | P165: 99
A166: =ROW()-3 -> 163 | B166: VIP精品课 | C166: 岗位课 | D166: 金融理财 | E166: 财富管理与资产配置 | F166: 规避人性的理财攻略 | G166: 规避人性的理财攻略 | H166: 戴翀 | I166: 视频 | J166: 全员 | K166: 基层管理者、职场新人 | L166: 44563 | M166: 16 | N166: 1.6169444 | O166: 已完结 | P166: 69
A167: =ROW()-3 -> 164 | B167: VIP精品课 | C167: 岗位课 | D167: 金融理财 | E167: 财富管理与资产配置 | F167: 港股打新如何提高中签率 | G167: 港股打新如何提高中签率 | H167: 刘怡伶 | I167: 视频 | J167: 全员 | K167: 基层管理者、职场新人 | L167: 44563 | M167: 11 | N167: 1.1744444 | O167: 已完结 | P167: 99
A168: =ROW()-3 -> 165 | B168: VIP精品课 | C168: 岗位课 | D168: 客户服务 | E168: 服务技巧 | F168: 透过结构看客户思维 | G168: 透过结构看客户思维 | H168: 覃曦 | I168: 视频 | J168: 全员 | K168: 基层管理者、中层管理者、职场新人 | L168: 44563 | M168: 12 | N168: 2.4947222 | O168: 已完结 | P168: 99
A169: =ROW()-3 -> 166 | B169: VIP精品课 | C169: 岗位课 | D169: 人力资源 | E169: 培训与开发 | F169: BEST高能经验萃取 | G169: BEST高能经验萃取 | H169: 邱伟 | I169: 视频 | J169: 全员 | K169: 基层管理者、中层管理者、职场新人 | L169: 44563 | M169: 13 | N169: 3.1302778 | O169: 已完结 | P169: 189
A170: =ROW()-3 -> 167 | B170: VIP精品课 | C170: 岗位课 | D170: 人力资源 | E170: 培训与开发 | F170: FAST高效课程开发 | G170: FAST高效课程开发 | H170: 邱伟 | I170: 视频 | J170: 全员 | K170: 基层管理者、中层管理者、专业人士 | L170: 44563 | M170: 17 | N170: 4.1327778 | O170: 已完结 | P170: 189
A171: =ROW()-3 -> 168 | B171: VIP精品课 | C171: 岗位课 | D171: 财务 | E171: 管理会计 | F171: 一名崩溃企业家的财务分析 | G171: 一名崩溃企业家的财务分析 | H171: 朱丽雅 | I171: 视频 | J171: 创始人、管理者 | K171: 高层管理者、专业人士 | L171: 44563 | M171: 14 | N171: 1.6863889 | O171: 已完结 | P171: 69
A172: =ROW()-3 -> 169 | B172: VIP精品课 | C172: 岗位课 | D172: 财务 | E172: 税务管理 | F172: 秒懂的电商财税风险管理 | G172: 秒懂的电商财税风险管理 | H172: 陶雯 | I172: 视频 | J172: 创始人、管理者 | K172: 中层管理者、高层管理者、专业人士 | L172: 44563 | M172: 15 | N172: 2.1155556 | O172: 已完结 | P172: 199
A173: =ROW()-3 -> 170 | B173: VIP精品课 | C173: 岗位课 | D173: 财务 | E173: 税务管理 | F173: 解救创业焦虑的财税课 | G173: 创业型公司的财务解决方案 | H173: 惠玉 | I173: 视频 | J173: 创始人、管理者 | K173: 中层管理者、高层管理者、专业人士 | L173: 44563 | M173: 25 | N173: 2.2175 | O173: 已完结 | P173: 199
A174: =ROW()-3 -> 171 | B174: VIP精品课 | C174: 岗位课 | D174: 金融理财 | E174: 财富管理与资产配置 | F174: 一门课学会基金投资 | G174: 基金上万只，怎么挑？ | H174: 黎京林 | I174: 视频 | J174: 管理者、财务 | K174: 专业人士 | L174: 44566 | M174: 16 | N174: 2.6 | O174: 未完结 | P174: 39
A175: =ROW()-3 -> 172 | B175: VIP精品课 | C175: 岗位课 | D175: 金融理财 | E175: 财富管理与资产配置 | F175: 公募基金的投资攻略课 | G175: 公募基金的投资攻略课 | H175: 黎京林 | I175: 视频 | J175: 全员 | K175: 基层管理者、中层管理者、职场新人 | L175: 44566 | M175: 17 | N175: 17 | O175: 更新中 | P175: 39
A176: =ROW()-3 -> 173 | B176: VIP精品课 | C176: 岗位课 | D176: 金融理财 | E176: 财富管理与资产配置 | F176: 新手投资者的数学投资思维课 | G176: 小白秒懂的数学投资思维 | H176: 顾艳 | I176: 视频 | J176: 全员 | K176: 基层管理者、中层管理者、职场新人 | L176: 44566 | M176: 22 | N176: 2.8519444 | O176: 已完结 | P176: 69
... A200: =ROW()-3 -> 197 | B200: VIP精品课 | C200: 商学院 | D200: 组织管理 | E200: 中层 | F200: 精益组织变革管理 | G200: 精益组织变革管理 | H200: 刘诚 | I200: 视频 | J200: 管理者 | K200: 中高层管理者 | L200: 44627 | M200: 10 | N200: 2.1 | O200: 已完结 | P200: 399
A201: =ROW()-3 -> 198 | B201: VIP精品课 | C201: 商学院 | D201: 战略规划 | E201: 高层 | F201: 张思宏：亚马逊增长双飞轮 | G201: 张思宏：亚马逊增长双飞轮 | H201: 张思宏 | I201: 视频 | J201: 管理者 | K201: 中层管理者，高层管理者 | L201: 44634 | M201: 20 | N201: 4.6 | O201: 已完结
A202: =ROW()-3 -> 199 | B202: VIP精品课 | C202: 其他 | D202: 职场技能 | E202: 职场认知 | F202: 张萌：高效打造个人品牌 | G202: 剖析自身实战经验，高效打造个人品牌养成方法 | H202: 张萌 | I202: 音频 | J202: 全员 | K202: 基层管理者、职场新人 | L202: 43238 | M202: 6 | N202: 1.09 | O202: 已完结 | P202: 9.9
A203: =ROW()-3 -> 200 | B203: VIP精品课 | C203: 其他 | D203: 人文社科 | E203: 情感心理 | F203: 袁春楠：脱胎换骨的人生整理术 | G203: 摆脱焦虑，重整人生、生活、职场、财富，轻装前行 | H203: 袁春楠 | I203: 音频 | J203: 全员 | K203: 中层管理者 | L203: 43238 | M203: 79 | N203: 24.04 | O203: 已完结 | P203: 199
A204: =ROW()-3 -> 201 | B204: VIP精品课 | C204: 其他 | D204: 人文社科 | E204: 人文历史 | F204: 周濂讲西方哲学智慧 | G204: 助你锻炼批判性思维，培养思考的逻辑性，更冷静有效地解决当下的问题 | H204: 周濂 | I204: 音频 | J204: 全员 | K204: 中层管理者 | L204: 43238 | M204: 101 | N204: 28.52 | O204: 已完结 | P204: 199
A205: =ROW()-3 -> 202 | B205: VIP精品课 | C205: 其他 | D205: 市场营销 | E205: 营销思维 | F205: 路长全营销课堂:改变命运的200条秘笈 | G205: 营销泰斗亲授，150堂课让你学会200个营销秘笈 | H205: 路长全 | I205: 音频 | J205: 销售、市场品牌 | K205: 中层管理者、专业人士 | L205: 43262 | M205: 153 | N205: 30.6 | O205: 已完结 | P205: 199
A206: =ROW()-3 -> 203 | B206: VIP精品课 | C206: 其他 | D206: 法律 | E206: 法律 | F206: 企业专利：驾驭未来商业的利器 | G206: 企业专利：驾驭未来商业的利器 | H206: 汤雄军 | I206: 音频 | J206: CEO、法务 | K206: 专业人士 | L206: 43321 | M206: 25 | N206: 4.82 | O206: 已完结 | P206: 59
A207: =ROW()-3 -> 204 | B207: VIP精品课 | C207: 其他 | D207: 人文社科 | E207: 亲子教育 | F207: 如何提升孩子的英语阅读理解能力 | G207: 原新东方名师带你打破英语阅读理解的壁垒 | H207: 孙健 | I207: 音频 | J207: 全员 | K207: 不限 | L207: 43381 | M207: 15 | N207: 3.08 | O207: 已完结 | P207: 99
A208: =ROW()-3 -> 205 | B208: VIP精品课 | C208: 其他 | D208: 人文社科 | E208: 人文历史 | F208: 为生命找道理 | G208: 前台湾大学哲学系教授为你透析人生哲学 | H208: 林火旺 | I208: 音频 | J208: 全员 | K208: 中层管理者 | L208: 43388 | M208: 257 | N208: 40.37 | O208: 已完结 | P208: 199
A209: =ROW()-3 -> 206 | B209: VIP精品课 | C209: 其他 | D209: 市场营销 | E209: 销售管理 | F209: 阿里铁军内训销售课 | G209: 阿里铁军10年10000人实战销售经验 | H209: 李立恒 | I209: 音频 | J209: 销售 | K209: 中层管理者、专业人士 | L209: 43573 | M209: 57 | N209: 12.8 | O209: 未完结 | P209: 99
A210: =ROW()-3 -> 207 | B210: VIP精品课 | C210: 其他 | D210: 法律 | E210: 法律 | F210: 如何打造安全的互联网内容公司 | G210: 规避内容政策风险，把握内容创新尺度 | H210: 压舱石 | I210: 音频 | J210: CEO、法务 | K210: 专业人士 | L210: 43598 | M210: 17 | N210: 2.66 | O210: 未完结 | P210: 198
...

Sheet 通用课
A1: 通用课频道
A2: 序号 | B2: 内容大类 | C2: 频道页 | D2: 一级标签 | E2: 二级标签 | F2: 课程名称 | G2: 副标题 | H2: 主讲人 | I2: 课程形式 | J2: 轻学堂上架日期 | K2: 课程总课时/集 | L2: 已上架课时总时间/h | M2: 更新状态 | N2: 单卖价格/元
A3: =ROW()-2 -> 1 | B3: VIP精品课 | C3: 通用课 | D3: 高效办公 | E3: 时间管理 | F3: 叶武滨时间管理10堂课-易效能 | G3: 时间管理10堂课，教你如何更有效率地工作和生活 | H3: 叶武滨 | I3: 音频 | J3: 43238 | K3: 20 | L3: 7.4641667 | M3: 已完结 | N3: 198
A4: =ROW()-2 -> 2 | B4: VIP精品课 | C4: 通用课 | D4: 高效办公 | E4: 工作方法 | F4: 薪资进阶手册：BAT工作法 | G4: 带你洞悉加薪本质，掌握名企工作法，带你摆脱焦虑，找准努力方向 | H4: 鲍艾乐 | I4: 音频 | J4: 43238 | K4: 150 | L4: 17.7025 | M4: 已完结 | N4: 99
A5: =ROW()-2 -> 3 | B5: VIP精品课 | C5: 通用课 | D5: 高效办公 | E5: 工作方法 | F5: 尹志豪：高效竞争力 | G5: 最高的效率达成目标，实现梦想的使用原理和方法 | H5: 尹志豪 | I5: 音频 | J5: 43318 | K5: 72 | L5: 15.259722 | M5: 已完结 | N5: 199
A6: =ROW()-2 -> 4 | B6: VIP精品课 | C6: 通用课 | D6: 高效办公 | E6: 办公工具 | F6: Excel零基础极速入门教程 | G6: 零基础迅速掌握职场高效技能 | H6: 秦川 | I6: 视频 | J6: 43417 | K6: 34 | L6: 3.8472222 | M6: 已完结 | N6: 99
A7: =ROW()-2 -> 5 | B7: VIP精品课 | C7: 通用课 | D7: 高效办公 | E7: 办公工具 | F7: Excel图表职场商务制作教程 | G7: Excel商务图表的精度，决定你工资的厚度 | H7: 秦川 | I7: 视频 | J7: 43426 | K7: 19 | L7: 7.3119444 | M7: 已完结 | N7: 99
A8: =ROW()-2 -> 6 | B8: VIP精品课 | C8: 通用课 | D8: 高效办公 | E8: 办公工具 | F8: Outlook职场快速上手教程 | G8: 职场邮件管理与工作事务管理利器 | H8: 秦川 | I8: 视频 | J8: 43427 | K8: 40 | L8: 2.9275 | M8: 已完结 | N8: 50
A9: =ROW()-2 -> 7 | B9: VIP精品课 | C9: 通用课 | D9: 高效办公 | E9: 办公工具 | F9: photoshop零基础极速入门教程 | G9: 掌握PS图片处理技能，小白也能出作品 | H9: 秦川 | I9: 视频 | J9: 43427 | K9: 50 | L9: 7.6994444 | M9: 已完结 | N9: 99
A10: =ROW()-2 -> 8 | B10: VIP精品课 | C10: 通用课 | D10: 高效办公 | E10: 办公工具 | F10: Word排版教程 | G10: 只有深知word原理，才能搞定word排版 | H10: 秦川 | I10: 视频 | J10: 43430 | K10: 33 | L10: 3.9175 | M10: 更新中 | N10: 50
A11: =ROW()-2 -> 9 | B11: VIP精品课 | C11: 通用课 | D11: 高效办公 | E11: 办公工具 | F11: PPT图形高效绘制教程 | G11: PPT做得好，下班回得早！ | H11: 秦川 | I11: 视频 | J11: 43430 | K11: 10 | L11: 2.4908333 | M11: 已完结 | N11: 59
A12: =ROW()-2 -> 10 | B12: VIP精品课 | C12: 通用课 | D12: 高效办公 | E12: 时间管理 | F12: 跟大神学实用时间管理术 | G12: 最顺应人性的时间管理课程 | H12: 纪元 | I12: 音频 | J12: 43571 | K12: 59 | L12: 7.5022222 | M12: 已完结 | N12: 99
A13: =ROW()-2 -> 11 | B13: VIP精品课 | C13: 通用课 | D13: 高效办公 | E13: 办公工具 | F13: 平面设计：创意思维成长 | G13: 学习如何进行视觉交流 | H13: Michael Loos | I13: 视频 | J13: 43663 | K13: 14 | L13: 5.9477778 | M13: 已完结 | N13: 66
A14: =ROW()-2 -> 12 | B14: VIP精品课 | C14: 通用课 | D14: 高效办公 | E14: 工作方法 | F14: 方军：60项硅谷高效工作法 | G14: 系统学习超级个体工作法与团队工作法 | H14: 方军 | I14: 音频 | J14: 43690 | K14: 73 | L14: 9.6747222 | M14: 已完结 | N14: 180
... A39: =ROW()-2 -> 37 | B39: VIP精品课 | C39: 通用课 | D39: 高效办公 | E39: 办公工具 | F39: 秦川：PPT标准化高效制作设计 | G39: 秦川：PPT标准化高效制作设计 | H39: 秦川 | I39: 视频 | J39: 44627 | K39: 9 | L39: 2.3 | M39: 已完结 | N39: 129
A40: =ROW()-2 -> 38 | B40: VIP精品课 | C40: 通用课 | D40: 高效办公 | E40: 目标管理 | F40: 目标管理 | G40: 目标管理 | H40: 新风向 | I40: 视频 | J40: 管理者 | K40: 中层管理者，高层管理者 | L40: 44634 | M40: 7 | N40: 0.8 | O40: 已完结
A41: =ROW()-2 -> 39 | B41: VIP精品课 | C41: 通用课 | D41: 沟通表达 | E41: 文案写作 | F41: 维佳：通向晋升之路的职场写作课 | G41: 每期一个职场写作小技巧，迅速提升职场写作功力，助你成为职场达人 | H41: 维佳 | I41: 音频 | J41: 43227 | K41: 33 | L41: 4.6330556 | M41: 已完结 | N41: 58
A42: =ROW()-2 -> 40 | B42: VIP精品课 | C42: 通用课 | D42: 沟通表达 | E42: 高效沟通 | F42: 奥美达人沟通课：重塑职场竞争力 | G42: 职场如何进行有效沟通，带你揭秘职场加薪晋升秘笈 | H42: 丁菱娟 | I42: 音频 | J42: 43238 | K42: 23 | L42: 2.5863889 | M42: 已完结 | N42: 49
A43: =ROW()-2 -> 41 | B43: VIP精品课 | C43: 通用课 | D43: 沟通表达 | E43: 高效沟通 | F43: 超级聊天术：如何成为沟通高手 | G43: 沟通高手如何练就超级聊天术=人脉通行证+社会竞争力+超强适应 | H43: 张大鹏 | I43: 音频 | J43: 43238 | K43: 39 | L43: 8.1741667 | M43: 已完结 | N43: 99
A44: =ROW()-2 -> 42 | B44: VIP精品课 | C44: 通用课 | D44: 沟通表达 | E44: 谈判 | F44: 快速谈判：用博弈技巧搞定交往难题 | G44: 美国大使馆三次、阿里巴巴27次特邀，谈判专家李力刚主讲 | H44: 李力刚 | I44: 音频 | J44: 43238 | K44: 24 | L44: 4.15 | M44: 已完结 | N44: 68
A45: =ROW()-2 -> 43 | B45: VIP精品课 | C45: 通用课 | D45: 沟通表达 | E45: 演讲 | F45: 从小白到演讲高手 | G45: 帮你收获最精华的演讲技巧，助你获得好口才，改变人生 | H45: 龙兄 | I45: 音频 | J45: 43238 | K45: 32 | L45: 5.9369444 | M45: 已完结 | N45: 99
A46: =ROW()-2 -> 44 | B46: VIP精品课 | C46: 通用课 | D46: 沟通表达 | E46: 高效沟通 | F46: 乐嘉性格色彩·读心术 | G46: 了解每种性格的优势和过当，找到人与人最平衡的相处之道。 | H46: 乐嘉 | I46: 音频 | J46: 43238 | K46: 111 | L46: 33.6225 | M46: 已完结 | N46: 199
A47: =ROW()-2 -> 45 | B47: VIP精品课 | C47: 通用课 | D47: 沟通表达 | E47: 高效沟通/说服 | F47: 马东携奇葩天团亲授“好好说话” | G47: 避开沟通雷区，把话说得漂亮得体，听一门不容错过的说话课 | H47: 米果文化 | I47: 音频 | J47: 43238 | K47: 280 | L47: 32.7425 | M47: 更新中 | N47: 198
A48: =ROW()-2 -> 46 | B48: VIP精品课 | C48: 通用课 | D48: 沟通表达 | E48: 演讲 | F48: 龙兄：跟乔布斯学演讲 | G48: 5节精品课，收获大师级演讲技巧 | H48: 龙兄 | I48: 音频 | J48: 43318 | K48: 7 | L48: 1.0577778 | M48: 已完结 | N48: 9.9
A49: =ROW()-2 -> 47 | B49: VIP精品课 | C49: 通用课 | D49: 沟通表达 | E49: 文案写作 | F49: 灵感来了：李欣频的文案创意课 | G49: 从内核到实战，带你全面升级文案功力​ | H49: 李欣频 | I49: 音频 | J49: 43759 | K49: 55 | L49: 11.2025 | M49: 已完结 | N49: 199
A50: =ROW()-2 -> 48 | B50: VIP精品课 | C50: 通用课 | D50: 沟通表达 | E50: 谈判 | F50: 谈判的72战术 | G50: 吴晓波、黄执中、伍思凯也在听的谈判课 | H50: 游梓翔 | I50: 音频 | J50: 43832 | K50: 40 | L50: 7.1666667 | M50: 已完结 | N50: 99
A51: =ROW()-2 -> 49 | B51: VIP精品课 | C51: 通用课 | D51: 沟通表达 | E51: 高效沟通/说服 | F51: 闪燕：关键对话 | G51: 成为冲突时刻的对话高手 | H51: 闪燕 | I51: 音频 | J51: 44032 | K51: 14 | L51: 2.5327778 | M51: 已完结 | N51: 99
A52: =ROW()-2 -> 50 | B52: VIP精品课 | C52: 通用课 | D52: 沟通表达 | E52: 说服 | F52: 韩焱：成为说服高手的心理课 | G52: 劝服自己，影响大众 | H52: 韩焱 | I52: 音频 | J52: 44126 | K52: 79 | L52: 19.671667 | M52: 已完结 | N52: 99
... A70: =ROW()-2 -> 68 | B70: VIP精品课 | C70: 通用课 | D70: 沟通表达 | E70: 文案写作 | F70: 徐公子的阅读成长课10讲 | G70: 徐公子的阅读成长课10讲 | H70: 徐玉贞 | I70: 音频 | J70: 44517 | K70: 11 | L70: 1.915 | M70: 已完结 | N70: 69
A71: =ROW()-2 -> 69 | B71: VIP精品课 | C71: 通用课 | D71: 沟通表达 | E71: 工作汇报 | F71: 朱老丝：有说服力的工作汇报 | G71: 朱老丝：有说服力的工作汇报 | H71: 朱老丝 | I71: 音频 | J71: 44533 | K71: 12 | L71: 1.6386111 | M71: 已完结
A72: =ROW()-2 -> 70 | B72: VIP精品课 | C72: 通用课 | D72: 沟通表达 | E72: 文案写作 | F72: 营销实战 | G72: 软文写作与销售文案 | H72: 林杉 | I72: 音频 | J72: 44538 | K72: 9 | L72: 0.81083333 | M72: 已完结 | N72: 19
A73: =ROW()-2 -> 71 | B73: VIP精品课 | C73: 通用课 | D73: 沟通表达 | E73: 高效沟通 | F73: 即兴表达 | G73: 用得上的8个说话秘笈 | H73: 卿杨剑 | I73: 音频 | J73: 44538 | K73: 24 | L73: 5.5297222 | M73: 已完结
A74: =ROW()-2 -> 72 | B74: VIP精品课 | C74: 通用课 | D74: 沟通表达 | E74: 高效沟通 | F74: 用声音搞定成交 | G74: 用声音搞定成交 | H74: 涂梦珊 | I74: 音频 | J74: 全员 | K74: 不限 | L74: 44509 | M74: 26 | N74: 3.53 | O74: 已完结 | P74: 99
A75: =ROW()-2 -> 73 | B75: VIP精品课 | C75: 通用课 | D75: 沟通表达 | E75: 谈判 | F75: 24招变身谈判专家 | G75: 24招变身谈判专家 | H75: 王詠 | I75: 音频 | J75: 全员 | K75: 不限 | L75: 44509 | M75: 25 | N75: 3.86 | O75: 已完结 | P75: 99
A76: =ROW()-2 -> 74 | B76: VIP精品课 | C76: 通用课 | D76: 沟通表达 | E76: 高效沟通 | F76: 李筱懿的职场智慧15条 | G76: 李筱懿的职场智慧15条 | H76: 李筱懿 | I76: 音频 | J76: 全员 | K76: 不限 | L76: 44509 | M76: 16 | N76: 2.54 | O76: 已完结 | P76: 99
A77: =ROW()-2 -> 75 | B77: VIP精品课 | C77: 通用课 | D77: 逻辑思维 | E77: 结构思考 | F77: 职场思维实战20讲 | G77: 逻辑助力职场，思维改变人生；有效提升你的逻辑思维力！ | H77: 耿人健 | I77: 音频 | J77: 43420 | K77: 24 | L77: 4.6563889 | M77: 已完结 | N77: 99
A78: =ROW()-2 -> 76 | B78: VIP精品课 | C78: 通用课 | D78: 逻辑思维 | E78: 结构思考 | F78: 六顶思考帽 | G78: 高效思考的14堂必修课 | H78: 曾婷 | I78: 音频 | J78: 43536 | K78: 14 | L78: 2.6769444 | M78: 已完结 | N78: 69
A79: =ROW()-2 -> 77 | B79: VIP精品课 | C79: 通用课 | D79: 逻辑思维 | E79: 认知思维 | F79: 陈昌凯的心理学课 | G79: 100讲详解心理学原理，从源头重构你的认知体系 | H79: 陈昌凯 | I79: 音频 | J79: 43945 | K79: 103 | L79: 23.793056 | M79: 已完结 | N79: 199
A80: =ROW()-2 -> 78 | B80: VIP精品课 | C80: 通用课 | D80: 逻辑思维 | E80: 结构思考 | F80: 结构思考力 | G80: 最简单、直接和有效的结构思考力训练方法 | H80: 李忠秋 | I80: 音频 | J80: 43960 | K80: 13 | L80: 2.0761111 | M80: 已完结 | N80: 199
A81: =ROW()-2 -> 79 | B81: VIP精品课 | C81: 通用课 | D81: 逻辑思维 | E81: 认知思维 | F81: 全球精英的5分钟成长学院 | G81: 为你交付一套“巨人”的思维工具 | H81: 喜马听世界 | I81: 音频 | J81: 43978 | K81: 504 | L81: 56.043889 | M81: 更新中 | N81: 199
...

Sheet 岗位课
A1: 岗位课频道
A2: 序号 | B2: 内容大类 | C2: 频道页 | D2: 一级标签 | E2: 二级标签 | F2: 课程名称 | G2: 副标题 | H2: 主讲人 | I2: 课程形式 | J2: 轻学堂上架日期 | K2: 课程总课时/集 | L2: 已上架课时总时间/h | M2: 更新状态 | N2: 单卖价格/元
A3: =ROW()-2 -> 1 | B3: VIP精品课 | C3: 岗位课 | D3: 财务 | E3: 管理会计 | F3: 优秀财务必须掌握的5大核心能力 | G3: 突破财务职业发展的困境，拒绝成为考证达人 | H3: 小安 | I3: 视频 | J3: 43570 | K3: 71 | L3: 26.369444 | M3: 已完结 | N3: 188
A4: =ROW()-2 -> 2 | B4: VIP精品课 | C4: 岗位课 | D4: 财务 | E4: 财资管理 | F4: 肖星的财务课 | G4: 从财务思维看职场，提升工作中的硬实力 | H4: 肖星 | I4: 音频 | J4: 43912 | K4: 72 | L4: 20.74 | M4: 已完结 | N4: 199
A5: =ROW()-2 -> 3 | B5: VIP精品课 | C5: 岗位课 | D5: 财务 | E5: 管理会计 | F5: 投行大师兄的财报速读课 | G5: 深入浅出讲清楚财务分析方法，挖掘有价值的公司 | H5: 吴晓波频道 | I5: 音频 | J5: 43916 | K5: 33 | L5: 4.6575 | M5: 已完结 | N5: 199
A6: =ROW()-2 -> 4 | B6: VIP精品课 | C6: 岗位课 | D6: 财务 | E6: 财资管理 | F6: 韩坤珏: 财务经理实战指南30讲 | G6: 韩坤珏: 财务经理实战指南30讲 | H6: 韩坤珏 | I6: 音频 | J6: 44517 | K6: 31 | L6: 7.9686111 | M6: 已完结 | N6: 99
A7: =ROW()-2 -> 5 | B7: VIP精品课 | C7: 岗位课 | D7: 财务 | E7: 管理会计/财资管理 | F7: 张新民的财报分析实战课38讲 | G7: 张新民教授的财务分析实战课38讲 | H7: 张新民 | I7: 视频 | J7: 44526 | K7: 38 | L7: 13.922222 | M7: 已完结 | N7: 169
A8: =ROW()-2 -> 6 | B8: VIP精品课 | C8: 岗位课 | D8: 财务 | E8: 管理会计 | F8: CFO手把手教你读懂财报 | G8: CFO手把手教你读懂财报 | H8: 郑永强 | I8: 音频 | J8: 44531 | K8: 11 | L8: 2.01 | M8: 已完结 | N8: 49
A9: =ROW()-2 -> 7 | B9: VIP精品课 | C9: 岗位课 | D9: 财务 | E9: 管理会计/税务管理 | F9: 财务管理课：非财务人员的财务管理 | G9: 财务管理课：非财务人员的财务管理 | H9: 郝卯花 | I9: 视频 | J9: 44534 | K9: 36 | L9: 7.7336111 | M9: 已完结 | N9: 199
A10: =ROW()-2 -> 8 | B10: VIP精品课 | C10: 岗位课 | D10: 财务 | E10: 财资管理/管理会计 | F10: 财务管理：现金流分析与营运资本管理 | G10: 财务管理：现金流分析与营运资本管理 | H10: 王艳 | I10: 视频 | J10: 44534 | K10: 20 | L10: 3.0633333 | M10: 已完结 | N10: 199
A11: =ROW()-2 -> 9 | B11: VIP精品课 | C11: 岗位课 | D11: 财务 | E11: 财务会计/财资管理 | F11: 商业语言|快速掌握财务会计精髓 | G11: 帮助企业家从财务报表中看清企业管理中的相关要素 | H11: 江军民 | I11: 视频 | J11: 44546 | K11: 44 | L11: 8.0652778 | M11: 已完结 | N11: 199
A12: =ROW()-2 -> 10 | B12: VIP精品课 | C12: 岗位课 | D12: 财务 | E12: 税务管理 | F12: 三张报表学稽查 | G12: 三张报表学稽查 | H12: 徐箐 | I12: 音频 | J12: 44548 | K12: 15 | L12: 2.2969444 | M12: 已完结 | N12: 138
A13: =ROW()-2 -> 11 | B13: VIP精品课 | C13: 岗位课 | D13: 财务 | E13: 税务管理 | F13: 快速掌握增值税实务操作技巧 | G13: 快速掌握增值税实务操作技巧 | H13: 徐箐 | I13: 音频 | J13: 44548 | K13: 50 | L13: 9.4541667 | M13: 已完结 | N13: 129
A14: =ROW()-2 -> 12 | B14: VIP精品课 | C14: 岗位课 | D14: 财务 | E14: 税务管理 | F14: 涉税基础系列课 | G14: 涉税基础系列课 | H14: 徐箐 | I14: 音频 | J14: 44548 | K14: 19 | L14: 3.4538889 | M14: 已完结 | N14: 129
... A22: =ROW()-2 -> 20 | B22: VIP精品课 | C22: 岗位课 | D22: 产品 | E22: 产品规划/设计 | F22: 从0-1-N爆品持续引爆的密码 | G22: 爆品瘾力 | H22: 江新安 | I22: 视频 | J22: 44437 | K22: 16 | L22: 3.8652778 | M22: 已完结 | N22: 198
A23: =ROW()-2 -> 21 | B23: VIP精品课 | C23: 岗位课 | D23: 产品 | E23: 产品思维 | F23: 贾伟：产品三观与用户思维10讲 | G23: 产品三观10讲 | H23: 贾伟 | I23: 音频 | J23: 44532 | K23: 4 | L23: 0.60333333 | M23: 更新中
A24: =ROW()-2 -> 22 | B24: VIP精品课 | C24: 岗位课 | D24: 产品 | E24: 产品思维 | F24: 高雄勇：我在小米做爆品 | G24: 高雄勇：我在小米做爆品 | H24: 高雄勇 | I24: 视频 | J24: 44535 | K24: 50 | L24: 5.5466667 | M24: 已完结 | N24: 199
A25: =ROW()-2 -> 23 | B25: VIP精品课 | C25: 岗位课 | D25: 产品 | E25: 产品思维 | F25: 感性商业 | G25: 世界500强企业通用的用户体验增长方法论 | H25: 罗浩 | I25: 视频 | J25: 44535 | K25: 10 | L25: 1.5977778 | M25: 已完结 | N25: 59
A26: =ROW()-2 -> 24 | B26: VIP精品课 | C26: 岗位课 | D26: 产品 | E26: 产品思维 | F26: 10堂课打造系统产品思维 | G26: 10堂课打造系统产品思维 | H26: 水滴产品学院 | I26: 视频 | J26: 44537 | K26: 38 | L26: 21.093889 | M26: 已完结
A27: =ROW()-2 -> 25 | B27: VIP精品课 | C27: 岗位课 | D27: 产品 | E27: 产品规划/设计 | F27: 产品高手必修课 | G27: 系统化讲述产品知识，帮你从产品小白迈向产品高手！ | H27: 水滴产品学院 | I27: 视频 | J27: 44537 | K27: 15 | L27: 2.4097222 | M27: 已完结 | N27: 99
A28: =ROW()-2 -> 26 | B28: VIP精品课 | C28: 岗位课 | D28: 产品 | E28: 产品规划/设计 | F28: 腾讯产品方法18讲 | G28: 千款产品背后的关键思考 | H28: 腾讯讲师 | I28: 音频 | J28: 44538 | K28: 21 | L28: 4.6052778 | M28: 已完结 | N28: 49
A29: =ROW()-2 -> 27 | B29: VIP精品课 | C29: 岗位课 | D29: 产品 | E29: 产品思维 | F29: 华为的GTM操盘法：捕捉市场的必备法则|价值 | G29: 向华为学成功法宝：产品打造和GTM操盘 | H29: 王叶鹏 | I29: 视频 | J29: 44546 | K29: 12 | L29: 5.4483333 | M29: 已完结 | N29: 89
A30: =ROW()-2 -> 28 | B30: VIP精品课 | C30: 岗位课 | D30: 产品 | E30: 产品思维 | F30: 卓越产品经理如何思考 | G30: 掌握产品思维，掌握解决问题的综合性思维 | H30: 渊池先生 | I30: 音频 | J30: 44548 | K30: 53 | L30: 6.8336111 | M30: 已完结
A31: =ROW()-2 -> 29 | B31: VIP精品课 | C31: 岗位课 | D31: 金融理财 | E31: 股权投资 | F31: 王英军律师：创业时代 决胜股权 | G31: 王英军律师结合多次股权咨询的实战经验，为创业者制作的创业股权课程 | H31: 王英军 | I31: 音频 | J31: 43227 | K31: 57 | L31: 21.928056 | M31: 已完结 | N31: 198
A32: =ROW()-2 -> 30 | B32: VIP精品课 | C32: 岗位课 | D32: 金融理财 | E32: 金融知识与技能 | F32: 向松祚讲货币与金融 | G32: 货币是财富的载体，金融是时间的机器，看透货币本质，理解金融逻辑 | H32: 向松祚 | I32: 音频 | J32: 43293 | K32: 114 | L32: 19.706667 | M32: 已完结 | N32: 199
A33: =ROW()-2 -> 31 | B33: VIP精品课 | C33: 岗位课 | D33: 金融理财 | E33: 股权投资 | F33: 资本时代的股权战略 | G33: 从战略高度，带你掌握资本时代股权设计的道与术 | H33: 徐怀玉 | I33: 音频 | J33: 43439 | K33: 34 | L33: 5.7619444 | M33: 已完结 | N33: 99
A34: =ROW()-2 -> 32 | B34: VIP精品课 | C34: 岗位课 | D34: 金融理财 | E34: 金融知识与技能 | F34: 首席经济学家管清友的金融课 | G34: 9大金融工具看时局和行业大势，破解投资难题 | H34: 管清友 | I34: 音频 | J34: 43706 | K34: 43 | L34: 8.8069444 | M34: 已完结 | N34: 698
A35: =ROW()-2 -> 33 | B35: VIP精品课 | C35: 岗位课 | D35: 金融理财 | E35: 股权投资 | F35: 雷军、徐小平御用律师私房股权课 | G35: 理论+案例，带你了解股权的基本架构 | H35: 张明若 | I35: 音频 | J35: 43712 | K35: 20 | L35: 1.9491667 | M35: 已完结 | N35: 99
A36: =ROW()-2 -> 34 | B36: VIP精品课 | C36: 岗位课 | D36: 金融理财 | E36: 证券 | F36: 清华王茵田的期货期权等衍生品课 | G36: 来自清华MBA的主题投资课 | H36: 王茵田 | I36: 音频 | J36: 44019 | K36: 36 | L36: 6.0461111 | M36: 已完结 | N36: 99
A37: =ROW()-2 -> 35 | B37: VIP精品课 | C37: 岗位课 | D37: 金融理财 | E37: 财富管理与资产配置 | F37: 苏培科：精英投资指南25讲 | G37: CCTV财经评论员，带你寻找A股投资新机遇 | H37: 苏培科 | I37: 音频 | J37: 44056 | K37: 15 | L37: 2.7252778 | M37: 更新中 | N37: 99
A38: =ROW()-2 -> 36 | B38: VIP精品课 | C38: 岗位课 | D38: 金融理财 | E38: 股权投资 | F38: 张晓丽：中小企业如何融资及上市 | G38: 风投专家教你为企业上市铺路 | H38: 张晓丽 | I38: 视频 | J38: 44061 | K38: 43 | L38: 7.6794444 | M38: 已完结 | N38: 199
A39: =ROW()-2 -> 37 | B39: VIP精品课 | C39: 岗位课 | D39: 金融理财 | E39: 审计风控 | F39: 企业法律风险必知 | G39: 企业经营千万条，知法懂法第一条 | H39: 京城律师天团 | I39: 音频 | J39: 44067 | K39: 62 | L39: 17.071667 | M39: 已完结 | N39: 198
A40: =ROW()-2 -> 38 | B40: VIP精品课 | C40: 岗位课 | D40: 金融理财 | E40: 股权投资 | F40: 陶矜：股权思维30讲 | G40: 股权名师手把手教你用活用股权 | H40: 陶矜 | I40: 音频 | J40: 44084 | K40: 33 | L40: 6.5802778 | M40: 已完结 | N40: 199
A41: =ROW()-2 -> 39 | B41: VIP精品课 | C41: 岗位课 | D41: 金融理财 | E41: 股权投资 | F41: 王英军律师：股权投资实战课 | G41: 王英军律师结合多次股权咨询的实战经验，为创业者制作的创业股权课程 | H41: 王英军 | I41: 音频 | J41: 44098 | K41: 33 | L41: 13.529444 | M41: 已完结 | N41: 198
A42: =ROW()-2 -> 40 | B42: VIP精品课 | C42: 岗位课 | D42: 金融理财 | E42: 财富管理与资产配置 | F42: 孙利平：论社会财富与企业利润 | G42: 教你从根源上理解商业的底层运作规律 | H42: 孙利平 | I42: 视频 | J42: 44141 | K42: 5 | L42: 3.6383333 | M42: 已完结 | N42: 99
... A52: =ROW()-2 -> 50 | B52: VIP精品课 | C52: 岗位课 | D52: 金融理财 | E52: 股权投资 | F52: 李芳：股权｜合伙｜股权设计｜分红 | G52: 付钱给对的人，而不是付钱给人 | H52: 李芳 | I52: 音频 | J52: 44539 | K52: 157 | L52: 14.363889 | M52: 已完结 | N52: 99
A53: =ROW()-2 -> 51 | B53: VIP精品课 | C53: 岗位课 | D53: 金融理财 | E53: 证券 | F53: 资产证券化与结构化金融 | G53: REITs实战 | H53: 宋光辉 | I53: 音频 | J53: 44539 | K53: 7 | L53: 1.4 | M53: 已完结
A54: =ROW()-2 -> 52 | B54: VIP精品课 | C54: 岗位课 | D54: 金融理财 | E54: 金融知识与技能 | F54: 倪云华：八步写出商业融资计划书 | G54: 倪云华：八步写出商业融资计划书 | H54: 倪云华 | I54: 视频 | J54: 44545 | K54: 11 | L54: 2.6447222 | M54: 已完结 | N54: 199
A55: =ROW()-2 -> 53 | B55: VIP精品课 | C55: 岗位课 | D55: 金融理财 | E55: 金融知识与技能 | F55: 律格资本：马博士的资本思维64讲 | G55: 律格资本：马博士的资本思维64讲 | H55: 马正 | I55: 视频 | J55: 44545 | K55: 19 | L55: 2.62 | M55: 已完结 | N55: 199
A56: =ROW()-2 -> 54 | B56: VIP精品课 | C56: 岗位课 | D56: 金融理财 | E56: 审计风控 | F56: 张宁：英文合同起草与审核 | G56: 快速全面的掌握英文合同起草和审核的专业知识 | H56: 张宁律师 | I56: 视频 | J56: 44548 | K56: 19 | L56: 12.612222 | M56: 已完结 | N56: 299
...

Sheet 商学院
A1: 商学院频道
A2: 序号 | B2: 内容大类 | C2: 频道页 | D2: 一级标签 | E2: 二级标签 | F2: 课程名称 | G2: 副标题 | H2: 主讲人 | I2: 课程形式 | J2: 轻学堂上架日期 | K2: 课程总课时/集 | L2: 已上架课时总时间/h | M2: 更新状态 | N2: 单卖价格/元
A3: =ROW()-2 -> 1 | B3: VIP精品课 | C3: 商学院 | D3: 管理认知 | E3: 基层 | F3: 陈雪频：新晋经理人十讲 | G3: 为商业管理提供世界级价值参考标准，推进企业管理实践与研究的国际化 | H3: 陈雪频 | I3: 音频 | J3: 43227 | K3: 14 | L3: 2.6933333 | M3: 已完结 | N3: 19.9
A4: =ROW()-2 -> 2 | B4: VIP精品课 | C4: 商学院 | D4: 管理认知 | E4: 中层 | F4: 叶阿次：高效管理100招 | G4: 100天迈向管人高手 | H4: 叶阿次 | I4: 音频 | J4: 43399 | K4: 102 | L4: 11.323056 | M4: 已完结 | N4: 99
A5: =ROW()-2 -> 3 | B5: VIP精品课 | C5: 商学院 | D5: 管理认知 | E5: 中层 | F5: 徐中：5分钟清晨领导课 | G5: 每天清晨5分钟领导力学习，先人一步获得成功 | H5: 徐中 | I5: 音频 | J5: 43553 | K5: 64 | L5: 6.64 | M5: 已完结 | N5: 99
A6: =ROW()-2 -> 4 | B6: VIP精品课 | C6: 商学院 | D6: 管理认知 | E6: 中层 | F6: 不懂带人，你就自己干到死 | G6: 管理更高效，带人更轻松 | H6: 姜颖远 | I6: 音频 | J6: 43605 | K6: 12 | L6: 1.5527778 | M6: 已完结 | N6: 49
A7: =ROW()-2 -> 5 | B7: VIP精品课 | C7: 商学院 | D7: 管理认知 | E7: 高层 | F7: 中国式管理【曾仕强原声版】 | G7: 尽揽领袖指挥，引领事业人生至高境界 | H7: 曾仕强 | I7: 音频 | J7: 43862 | K7: 24 | L7: 5.2063889 | M7: 已完结 | N7: 49.8
A8: =ROW()-2 -> 6 | B8: VIP精品课 | C8: 商学院 | D8: 管理认知 | E8: 中层 | F8: 樊登：可复制的领导力 | G8: 快速复制领导能力，破解管理难题 | H8: 樊登 | I8: 视频 | J8: 44004 | K8: 37 | L8: 5.5425 | M8: 已完结 | N8: 199
A9: =ROW()-2 -> 7 | B9: VIP精品课 | C9: 商学院 | D9: 管理认知 | E9: 高层 | F9: 西点军校最受欢迎的领导力课（视频版） | G9: 商界、政界、军界影响力最大的领导力法则 | H9: 拉里·杜尼嵩 | I9: 视频 | J9: 44012 | K9: 27 | L9: 5.9786111 | M9: 已完结 | N9: 199
A10: =ROW()-2 -> 8 | B10: VIP精品课 | C10: 商学院 | D10: 管理认知 | E10: 高层 | F10: 曾仕强教授讲中庸管理之道 | G10: 当企业管理遇上民族文化 | H10: 曾仕强 | I10: 视频 | J10: 44025 | K10: 126 | L10: 23.755 | M10: 已完结 | N10: 99
A11: =ROW()-2 -> 9 | B11: VIP精品课 | C11: 商学院 | D11: 管理认知 | E11: 中层 | F11: 彼得·德鲁克的管理学精讲 | G11: 彼得·德鲁克的管理学精讲 | H11: 李洁 | I11: 音频 | J11: 44089 | K11: 67 | L11: 24.372222 | M11: 已完结 | N11: 99
A12: =ROW()-2 -> 10 | B12: VIP精品课 | C12: 商学院 | D12: 管理认知 | E12: 高层 | F12: 阿里巴巴管理三板斧 | G12: 练好内功，向管理要效益 | H12: 许林芳 | I12: 视频 | J12: 44139 | K12: 12 | L12: 3.0916667 | M12: 已完结 | N12: 99
A13: =ROW()-2 -> 11 | B13: VIP精品课 | C13: 商学院 | D13: 管理认知 | E13: 基层 | F13: 新任经理人的管理必修课 | G13: 8招带你快速从管理自我向管理他人转变 | H13: 陈致宇 | I13: 视频 | J13: 44154 | K13: 10 | L13: 3.8116667 | M13: 已完结 | N13: 599
A14: =ROW()-2 -> 12 | B14: VIP精品课 | C14: 商学院 | D14: 管理认知 | E14: 基层 | F14: 高琳：新手管理者的30堂必修课 | G14: 为新手管理者扫除误区、深度赋能 | H14: 高琳 | I14: 音频 | J14: 44189 | K14: 31 | L14: 5.8352778 | M14: 已完结 | N14: 199
... A61: =ROW()-2 -> 59 | B61: VIP精品课 | C61: 商学院 | D61: 业务经营 | E61: 中层 | F61: 吴婷:快公司生长密码 | G61: 快公司生长密码 | H61: 吴婷 | I61: 音频 | J61: 44449 | K61: 10 | L61: 2.1658333 | M61: 已完结 | N61: 168
A62: =ROW()-2 -> 60 | B62: VIP精品课 | C62: 商学院 | D62: 业务经营 | E62: 基层 | F62: 超级创新力：设计思考企业实战攻略 | G62: 超级创新力：设计思考企业实战攻略 | H62: 刘恭甫 | I62: 音频 | J62: 管理者和HR | K62: 中层管理者，高层管理者、HR | L62: 44634 | M62: 11 | N62: 2.3 | O62: 未完结
A63: =ROW()-2 -> 61 | B63: VIP精品课 | C63: 商学院 | D63: 业务经营/战略规划 | E63: 高层 | F63: 湖畔三板斧：首次公开创业心法 | G63: 阿里合伙人亲授，回顾创业的关键节点、经验以及案例分析，传递决策背后的心法A | H63: 马云等 | I63: 音频 | J63: 43238 | K63: 62 | L63: 23.033333 | M63: 已完结 | N63: 99
A64: =ROW()-2 -> 62 | B64: VIP精品课 | C64: 商学院 | D64: 业务经营/组织发展 | E64: 中层 | F64: 陈春花：数字化企业管理实战课 | G64: 协同数字化时代组织效率的本质 | H64: 陈春花 | I64: 音频 | J64: 44410 | K64: 14 | L64: 1.2255556 | M64: 已完结 | N64: 199
A65: =ROW()-2 -> 63 | B65: VIP精品课 | C65: 商学院 | D65: 战略规划 | E65: 中层 | F65: 倪云华：全球商业模式创新40讲 | G65: 为企业找到十倍盈利突破点的视频课 | H65: 倪云华 | I65: 视频 | J65: 43579 | K65: 41 | L65: 4.6822222 | M65: 已完结 | N65: 99
A66: =ROW()-2 -> 64 | B66: VIP精品课 | C66: 商学院 | D66: 战略规划 | E66: 基层 | F66: 清华朱武祥的商业模式课 | G66: 用小资源撬动大财富，带你打开财富之门 | H66: 朱武祥 | I66: 音频 | J66: 43909 | K66: 56 | L66: 7.9288889 | M66: 已完结 | N66: 199
A67: =ROW()-2 -> 65 | B67: VIP精品课 | C67: 商学院 | D67: 战略规划 | E67: 中层 | F67: 清华名师王勇：活学活用博弈论 | G67: 深度解读博弈论精华 | H67: 王勇 | I67: 音频 | J67: 43941 | K67: 60 | L67: 14.685 | M67: 已完结 | N67: 199
A68: =ROW()-2 -> 66 | B68: VIP精品课 | C68: 商学院 | D68: 战略规划 | E68: 高层 | F68: 航运物流业遇到的困局及破解之道 | G68: 解析航运物流业痛点，提出针对性解决方案 | H68: 黄伟明 | I68: 音频 | J68: 43969 | K68: 10 | L68: 1.7188889 | M68: 已完结 | N68: 46
A69: =ROW()-2 -> 67 | B69: VIP精品课 | C69: 商学院 | D69: 战略规划 | E69: 基层 | F69: 蒋伟良：人人用得上的战略思维课 | G69: 前华为高管的战略课 | H69: 蒋伟良 | I69: 视频 | J69: 44078 | K69: 11 | L69: 2.5383333 | M69: 已完结 | N69: 129
A70: =ROW()-2 -> 68 | B70: VIP精品课 | C70: 商学院 | D70: 战略规划 | E70: 中层 | F70: 领导力@数字时代 | G70: 数字化转型是威胁也是机遇 | H70: 林奕威 | I70: 音频 | J70: 44123 | K70: 8 | L70: 1.3691667 | M70: 已完结 | N70: 99
A71: =ROW()-2 -> 69 | B71: VIP精品课 | C71: 商学院 | D71: 战略规划 | E71: 高层 | F71: 企业家必听柏翔解析BLM战略工具 | G71: 企业家必听柏翔解析BLM战略工具 | H71: 柏翔 | I71: 音频 | J71: 44509 | K71: 13 | L71: 2.1975 | M71: 已完结 | N71: 99
A72: =ROW()-2 -> 70 | B72: VIP精品课 | C72: 商学院 | D72: 战略规划 | E72: 高层 | F72: 商业模式：企业持续增长的双增长引擎|数字化转型 | G72: 商业模式：企业持续增长的双增长引擎 | H72: 高竞 | I72: 视频 | J72: 44531 | K72: 24 | L72: 3.8575 | M72: 已完结 | N72: 199
A73: =ROW()-2 -> 71 | B73: VIP精品课 | C73: 商学院 | D73: 战略规划 | E73: 高层 | F73: 如何运用BLM推动企业战略落地 | G73: |如何运用BLM推动企业战略落地 | H73: 佛洁 | I73: 音频 | J73: 44531 | K73: 32 | L73: 4.9922222 | M73: 已完结 | N73: 99
A74: =ROW()-2 -> 72 | B74: VIP精品课 | C74: 商学院 | D74: 战略规划 | E74: 基层 | F74: 战略管理 | G74: 北京大学教授陈择华主讲 | H74: 陈择华 | I74: 音频 | J74: 44531 | K74: 20 | L74: 3.0661111 | M74: 已完结 | N74: 19.9
... A76: =ROW()-2 -> 74 | B76: VIP精品课 | C76: 商学院 | D76: 战略规划 | E76: 基层 | F76: 从战略到成功的七大行动 | G76: 从战略到成功的七大行动 | H76: 新风向 | I76: 视频 | J76: 44620 | K76: 4 | L76: 0.5 | M76: 已完结 | N76: 64
A77: =ROW()-2 -> 75 | B77: VIP精品课 | C77: 商学院 | D77: 战略规划 | E77: 高层 | F77: 张思宏：亚马逊增长双飞轮 | G77: 张思宏：亚马逊增长双飞轮 | H77: 张思宏 | I77: 视频 | J77: 管理者 | K77: 中层管理者，高层管理者 | L77: 44634 | M77: 20 | N77: 4.6 | O77: 已完结
A78: =ROW()-2 -> 76 | B78: VIP精品课 | C78: 商学院 | D78: 组织发展 | E78: 基层 | F78: 倪云华的团队管理课 | G78: 最佳团队管理课系统方法论，为你定制最实用的团队管理课 | H78: 倪云华 | I78: 音频 | J78: 43238 | K78: 61 | L78: 10.276389 | M78: 已完结 | N78: 99
A79: =ROW()-2 -> 77 | B79: VIP精品课 | C79: 商学院 | D79: 组织发展 | E79: 中层 | F79: 孙陶然亲授：企业管理实战兵法 | G79: 管理企业，不仅知道做什么，而且知道怎么做 | H79: 孙陶然 | I79: 音频 | J79: 43321 | K79: 30 | L79: 4.785 | M79: 已完结 | N79: 99
A80: =ROW()-2 -> 78 | B80: VIP精品课 | C80: 商学院 | D80: 组织发展 | E80: 中层 | F80: 关苏哲：高效管理者的必备技能 | G80: 私董会总裁教练，带你全面学习管理技能 | H80: 关苏哲 | I80: 音频 | J80: 43488 | K80: 72 | L80: 13.571389 | M80: 更新中 | N80: 129
A81: =ROW()-2 -> 79 | B81: VIP精品课 | C81: 商学院 | D81: 组织发展 | E81: 高层 | F81: 实战三板斧 | 阿里巴巴管理模式 | G81: 破译阿里文化基因，揭秘阿里管理系统 | H81: 天机 | I81: 音频 | J81: 43563 | K81: 76 | L81: 20.003611 | M81: 已完结 | N81: 99
A82: =ROW()-2 -> 80 | B82: VIP精品课 | C82: 商学院 | D82: 组织发展 | E82: 基层 | F82: 倪云华：团队管理40条军规 | G82: 全网最受欢迎的团队管理视频课 | H82: 倪云华 | I82: 视频 | J82: 43579 | K82: 40 | L82: 3.5747222 | M82: 已完结 | N82: 99
A83: =ROW()-2 -> 81 | B83: VIP精品课 | C83: 商学院 | D83: 组织发展 | E83: 高层 | F83: 向心力阿米巴经营实战学 | G83: 结合中国企业实情，可落地的阿米巴经营实学 | H83: 何朝来 | I83: 音频 | J83: 43659 | K83: 59 | L83: 9.2888889 | M83: 更新中 | N83: 99
A84: =ROW()-2 -> 82 | B84: VIP精品课 | C84: 商学院 | D84: 组织发展 | E84: 高层 | F84: 吴建国：华为组织管理精要 | G84: 跟华为老将，学华为组织管理之道 | H84: 吴建国 | I84: 音频 | J84: 44053 | K84: 27 | L84: 5.0436111 | M84: 已完结 | N84: 199
A85: =ROW()-2 -> 83 | B85: VIP精品课 | C85: 商学院 | D85: 组织发展 | E85: 基层 | F85: 10人以下小团队管理手册：轻松带出高绩效团队 | G85: 释放小编队潜能，打造高绩效团队 | H85: 徐国允 | I85: 音频 | J85: 44175 | K85: 22 | L85: 3.6963889 | M85: 已完结 | N85: 99
A86: =ROW()-2 -> 84 | B86: VIP精品课 | C86: 商学院 | D86: 组织发展 | E86: 基层 | F86: 小团队高效管理手册 | G86: 28个小团队管理新知 | H86: 姜海舟 | I86: 音频 | J86: 44307 | K86: 29 | L86: 5.0083333 | M86: 已完结 | N86: 129
A87: =ROW()-2 -> 85 | B87: VIP精品课 | C87: 商学院 | D87: 组织发展 | E87: 中层 | F87: 管理者必备的24个管理工具 | G87: 顶级商学院必学的管理方法 | H87: 倪云华 | I87: 视频 | J87: 44357 | K87: 24 | L87: 5.8875 | M87: 已完结 | N87: 199
...

Sheet 书籍列表（总）
A1: 轻学堂—书籍列表
A2: 内容说明： 1. 适用VIP企业或已购买企业有声图书馆产品的企业，实现全员畅听，打造学习型组织。 2. 讲书，由专业团队编辑，挑选各领域的经典好书，每本书25分钟左右精华音频呈现。 3. 有声书，精听整本书籍，阅读新方式。轻学堂整合喜马拉雅海量、正版有声书资源，打造企业有声图书馆。
A3: 序号 | B3: 书籍大类 | C3: 分类 | D3: 书籍名称 | E3: 作者 | F3: 主讲人 | G3: 适听人群 | H3: 集数 | I3: 已上架课时总时间/h | J3: 轻学堂上架日期 | K3: 更新状态 | L3: 单卖价格/元
A4: =ROW()-3 -> 1 | B4: 讲书 | C4: 财经 | D4: 文明寻思录 | E4: 秦朔 | F4: 秦朔 | G4: 全员 | H4: 1 | I4: 0.63472222 | J4: 43468 | K4: 已完结 | L4: 4.99
A5: =ROW()-3 -> 2 | B5: 讲书 | C5: 财经 | D5: 经营分析与估值 | E5: 克雷沙·G·帕利普 | F5: 薛云奎 | G5: 全员 | H5: 1 | I5: 0.54777778 | J5: 43469 | K5: 已完结 | L5: 4.99
A6: =ROW()-3 -> 3 | B6: 讲书 | C6: 财经 | D6: 华尔街幽灵 | E6: 阿瑟·L·辛普森 | F6: 孟可 | G6: 全员 | H6: 1 | I6: 0.71916667 | J6: 43469 | K6: 已完结 | L6: 4.99
A7: =ROW()-3 -> 4 | B7: 讲书 | C7: 财经 | D7: 魔鬼经济学 | E7: 史蒂芬·列维特/史蒂芬·都伯纳 | F7: 元生 | G7: 全员 | H7: 1 | I7: 0.75722222 | J7: 43469 | K7: 已完结 | L7: 4.99
A8: =ROW()-3 -> 5 | B8: 讲书 | C8: 财经 | D8: 不平等的代价 | E8: 约瑟夫·E·斯蒂格利茨 | F8: 李长安 | G8: 全员 | H8: 1 | I8: 0.49472222 | J8: 43483 | K8: 已完结 | L8: 4.99
A9: =ROW()-3 -> 6 | B9: 讲书 | C9: 财经 | D9: 新财富管理 | E9: 哈罗德·埃文斯基，斯蒂芬·M·霍伦，托马斯·R·罗宾逊 | F9: 李清昊 | G9: 全员 | H9: 29 | I9: 8.8205556 | J9: 43483 | K9: 已完结 | L9: 4.99
A10: =ROW()-3 -> 7 | B10: 讲书 | C10: 财经 | D10: 1844年经济学哲学手稿 | E10: 卡尔·马克思 | F10: 薛晓明 | G10: 全员 | H10: 1 | I10: 0.40611111 | J10: 43962 | K10: 已完结 | L10: 4.99
A11: =ROW()-3 -> 8 | B11: 讲书 | C11: 财经 | D11: 游戏改变世界 | E11: 简·麦戈尼格尔 | F11: 英国报姐 | G11: 全员 | H11: 1 | I11: 0.35777778 | J11: 43962 | K11: 已完结 | L11: 4.99
A12: =ROW()-3 -> 9 | B12: 讲书 | C12: 财经 | D12: 爆裂 | E12: 伊藤穰一，杰夫·豪 | F12: 曹易伦 | G12: 全员 | H12: 1 | I12: 0.45055556 | J12: 43962 | K12: 已完结 | L12: 4.99
A13: =ROW()-3 -> 10 | B13: 讲书 | C13: 财经 | D13: 逃不开的经济周期 | E13: 拉斯·特维德 | F13: 魏强斌 | G13: 全员 | H13: 1 | I13: 0.42055556 | J13: 43962 | K13: 已完结 | L13: 4.99
A14: =ROW()-3 -> 11 | B14: 讲书 | C14: 财经 | D14: 行动的勇气 | E14: 本·伯南克 | F14: 李长安 | G14: 全员 | H14: 1 | I14: 0.46555556 | J14: 43962 | K14: 已完结 | L14: 4.99
A15: =ROW()-3 -> 12 | B15: 讲书 | C15: 财经 | D15: 引爆点 | E15: 马尔科姆·格拉德威尔 | F15: 耿人健 | G15: 全员 | H15: 1 | I15: 0.30138889 | J15: 43962 | K15: 已完结 | L15: 4.99
... A130: =ROW()-3 -> 127 | B130: 讲书 | C130: 财经 | D130: 极简法则 | E130: 理查德·科克 | F130: 西蒙 | G130: 全员 | H130: 1 | I130: 0.52 | J130: 44186 | K130: 已完结 | L130: 4.99
A131: =ROW()-3 -> 128 | B131: 讲书 | C131: 财经 | D131: 未来银行 | E131: 乔纳森·马米兰 | F131: 刘美 | G131: 全员 | H131: 1 | I131: 0.5 | J131: 44263 | K131: 已完结 | L131: 4..99
A132: =ROW()-3 -> 129 | B132: 讲书 | C132: 财经 | D132: 财富的起源 | E132: 埃里克·拜因霍克 | F132: 章永宏 | G132: 全员 | H132: 1 | I132: 0.5 | J132: 44522 | K132: 已完结 | L132: 4..99
A133: =ROW()-3 -> 130 | B133: 讲书 | C133: 财经 | D133: 中间人经济 | E133: 玛丽娜·克拉科夫斯基 | F133: 陈曦 | G133: 全员 | H133: 1 | I133: 0.5 | J133: 44543 | K133: 已完结 | L133: 4..99
A134: =ROW()-3 -> 131 | B134: 讲书 | C134: 财经 | D134: 一本书读懂财报 | E134: 肖星 | F134: 刘美 | G134: 全员 | H134: 1 | I134: 0.49 | J134: 44551 | K134: 已完结 | L134: 4.99
A135: =ROW()-3 -> 132 | B135: 讲书 | C135: 财经 | D135: 与运气竞争 | E135: 克莱顿·克里斯坦森 | F135: 陈曦 | G135: 全员 | H135: 1 | I135: 0.48 | J135: 44578 | K135: 已完结 | L135: 4..100
A136: =ROW()-3 -> 133 | B136: 讲书 | C136: 财经 | D136: 价值 | E136: 张磊 | F136: 武京丽 | G136: 全员 | H136: 1 | I136: 0.5 | J136: 44620 | K136: 已完结 | L136: 4.9
A137: =ROW()-3 -> 134 | B137: 讲书 | C137: 创业 | D137: 一胜九败：优衣库风靡全球的秘密 | E137: 柳井正 | F137: 徐静波 | G137: 全员 | H137: 1 | I137: 0.52888889 | J137: 43469 | K137: 已完结 | L137: 4.99
A138: =ROW()-3 -> 135 | B138: 讲书 | C138: 创业 | D138: 创新公司 | E138: 艾德·卡特姆/埃米·华莱士 | F138: 图南 | G138: 全员 | H138: 1 | I138: 0.46666667 | J138: 43962 | K138: 已完结 | L138: 4.99
A139: =ROW()-3 -> 136 | B139: 讲书 | C139: 创业 | D139: 疯传 | E139: 乔纳·伯杰 | F139: 周华明 | G139: 全员 | H139: 1 | I139: 0.73194444 | J139: 43962 | K139: 已完结 | L139: 4.99
A140: =ROW()-3 -> 137 | B140: 讲书 | C140: 创业 | D140: 一网打尽 | E140: 布拉德·斯通 | F140: 陈聪明 | G140: 全员 | H140: 1 | I140: 0.42777778 | J140: 43978 | K140: 已完结 | L140: 4.99
A141: =ROW()-3 -> 138 | B141: 讲书 | C141: 创业 | D141: 鞋狗 | E141: 菲尔·奈特 | F141: 邹大湿 | G141: 全员 | H141: 1 | I141: 0.56611111 | J141: 43978 | K141: 已完结 | L141: 4.99
A142: =ROW()-3 -> 139 | B142: 讲书 | C142: 创业 | D142: 孙正义：未来的机遇在哪里 | E142: 井上笃夫 | F142: 钱老师 | G142: 全员 | H142: 1 | I142: 1.9375 | J142: 43978 | K142: 已完结 | L142: 4.99
A143: =ROW()-3 -> 140 | B143: 讲书 | C143: 创业 | D143: 从0到1 | E143: 彼得·蒂尔 | F143: 沈攀 | G143: 全员 | H143: 1 | I143: 0.79277778 | J143: 43978 | K143: 已完结 | L143: 4.99
A144: =ROW()-3 -> 141 | B144: 讲书 | C144: 创业 | D144: 重新定义公司:谷歌是如何运营的 | E144: 埃里克·施密特/乔纳森·罗森伯格 | F144: 沈攀 | G144: 全员 | H144: 1 | I144: 0.4175 | J144: 43978 | K144: 已完结 | L144: 4.99
A145: =ROW()-3 -> 142 | B145: 讲书 | C145: 创业 | D145: Facebook效应 | E145: 大卫·柯克帕特里克 | F145: 韩春苗 | G145: 全员 | H145: 1 | I145: 0.55444444 | J145: 43978 | K145: 已完结 | L145: 4.99
A146: =ROW()-3 -> 143 | B146: 讲书 | C146: 创业 | D146: 硅谷钢铁侠 | E146: 阿什利·万斯 | F146: 高融 | G146: 全员 | H146: 1 | I146: 0.3075 | J146: 43978 | K146: 已完结 | L146: 4.99
A147: =ROW()-3 -> 144 | B147: 讲书 | C147: 创业 | D147: 单点突破 | E147: 张本伟/赵鑫 /杨琰华 | F147: 施襄 | G147: 全员 | H147: 1 | I147: 0.43944444 | J147: 43978 | K147: 已完结 | L147: 4.99
... A161: =ROW()-3 -> 158 | B161: 讲书 | C161: 创业 | D161: 微创新 | E161: 雅各布·哥登堡 | F161: 严智砾 | G161: 全员 | H161: 1 | I161: 0.4 | J161: 44102 | K161: 已完结 | L161: 4.99
A162: =ROW()-3 -> 159 | B162: 讲书 | C162: 创业 | D162: 翻转课堂的可汗学院 | E162: 萨尔曼·可汗 | F162: 陈曦 | G162: 全员 | H162: 1 | I162: 0.36 | J162: 44123 | K162: 已完结 | L162: 4..99
A163: =ROW()-3 -> 160 | B163: 讲书 | C163: 创业 | D163: 事实（上） | E163: 汉斯·罗斯林 | F163: 林伯虎 | G163: 全员 | H163: 1 | I163: 0.49555556 | J163: 44158 | K163: 已完结 | L163: 4.99
A164: =ROW()-3 -> 161 | B164: 讲书 | C164: 创业 | D164: 富甲美国 | E164: 山姆·沃尔顿 | F164: 果真 | G164: 全员 | H164: 1 | I164: 0.4 | J164: 44529 | K164: 已完结 | L164: 4.99
A165: =ROW()-3 -> 162 | B165: 讲书 | C165: 管理 | D165: 罗伯特议事规则 | E165: 亨利·罗伯特 | F165: 图南 | G165: 全员 | H165: 1 | I165: 0.36666667 | J165: 43468 | K165: 已完结 | L165: 4.99
A166: =ROW()-3 -> 163 | B166: 讲书 | C166: 管理 | D166: 驱动力 | E166: 丹尼尔·平克 | F166: 元生 | G166: 全员 | H166: 1 | I166: 0.405 | J166: 43468 | K166: 已完结 | L166: 4.99
A167: =ROW()-3 -> 164 | B167: 讲书 | C167: 管理 | D167: 商业的本质 | E167: 杰克·韦尔奇，苏茜·韦尔奇 | F167: 曾言 | G167: 全员 | H167: 1 | I167: 0.50305556 | J167: 43469 | K167: 已完结 | L167: 4.99
...

Sheet 有声书
A1: 有声书
A2: 序号 | B2: 书籍大类 | C2: 分类 | D2: 书籍名称 | E2: 作者 | F2: 主讲人 | G2: 适听人群 | H2: 集数 | I2: 已上架课时总时间/h | J2: 轻学堂上架日期 | K2: 更新状态 | L2: 单卖价格/元
A3: =ROW()-2 -> 1 | B3: 有声书 | C3: 财经 | D3: 读懂经济学的第一本书：国富论 | E3: 斯密 | F3: 子小苏 | G3: 全员 | H3: 115 | I3: 65.919167 | J3: 43273 | K3: 已完结 | L3: 99
A4: =ROW()-2 -> 2 | B4: 有声书 | C4: 财经 | D4: 李清昊带你精读40本投资经典 | E4: 亚当·斯密，本杰明·格雷厄姆，古斯塔夫·勒庞，吉姆·柯林斯，杰里·波勒斯 等 | F4: 李清昊 | G4: 全员 | H4: 27 | I4: 11.923333 | J4: 43325 | K4: 已完结 | L4: 99
A5: =ROW()-2 -> 3 | B5: 有声书 | C5: 财经 | D5: 檀书：叶檀的投资读书笔记 | E5: 彼得·考夫曼，贾雷德·戴蒙，彼得·林奇，约翰·罗瑟查尔德 等 | F5: 叶檀 | G5: 全员 | H5: 27 | I5: 11.923333 | J5: 43325 | K5: 已完结
A6: =ROW()-2 -> 4 | B6: 有声书 | C6: 财经 | D6: 非理性繁荣与金融危机 | E6: 罗伯特·席勒 | F6: 中信书院 | G6: 全员 | H6: 66 | I6: 23.936667 | J6: 43468 | K6: 已完结 | L6: 29.5
A7: =ROW()-2 -> 5 | B7: 有声书 | C7: 财经 | D7: 滚雪球：巴菲特和他的财富人生(上) | E7: 艾丽斯·施罗德 | F7: 中信书院 | G7: 全员 | H7: 40 | I7: 15.357222 | J7: 43468 | K7: 已完结 | L7: 90
A8: =ROW()-2 -> 6 | B8: 有声书 | C8: 财经 | D8: 魔鬼经济学系列 | E8: 史蒂芬·列维特 | F8: 中信书院 | G8: 全员 | H8: 52 | I8: 19.7 | J8: 43468 | K8: 已完结 | L8: 29.5
A9: =ROW()-2 -> 7 | B9: 有声书 | C9: 财经 | D9: 激荡十年，水大鱼大 | E9: 吴晓波 | F9: 蓝狮子FM | G9: 全员 | H9: 45 | I9: 15.616944 | J9: 43468 | K9: 已完结 | L9: 24.5
A10: =ROW()-2 -> 8 | B10: 有声书 | C10: 财经 | D10: 王传福传：比亚迪神话 | E10: 成杰 | F10: 司南时代 | G10: 全员 | H10: 28 | I10: 7.7316667 | J10: 43469 | K10: 已完结 | L10: 33.6
A11: =ROW()-2 -> 9 | B11: 有声书 | C11: 财经 | D11: 钓愚 | E11: 乔治·阿克洛夫 | F11: 中信书院 | G11: 全员 | H11: 22 | I11: 7.7125 | J11: 43469 | K11: 已完结 | L11: 29.5
A12: =ROW()-2 -> 10 | B12: 有声书 | C12: 财经 | D12: 穷查理宝典 | E12: 彼得·考夫曼 | F12: 中信书院 | G12: 全员 | H12: 45 | I12: 17.126389 | J12: 43469 | K12: 已完结 | L12: 19.9
A13: =ROW()-2 -> 11 | B13: 有声书 | C13: 财经 | D13: 销售女神董明珠书写商界传奇 | E13: 肖文键 | F13: 司南时代 | G13: 全员 | H13: 33 | I13: 11.003889 | J13: 43481 | K13: 已完结 | L13: 39.9
A14: =ROW()-2 -> 12 | B14: 有声书 | C14: 财经 | D14: 新制造时代：李书福与吉利、沃尔沃的超级制造 | E14: 王千马，梁冬梅 | F14: 狮声FM | G14: 全员 | H14: 23 | I14: 9.0175 | J14: 43483 | K14: 已完结 | L14: 6.99
A15: =ROW()-2 -> 13 | B15: 有声书 | C15: 财经 | D15: 互联网金融九堂课 | E15: 谢平 | F15: 一度和围脖 | G15: 全员 | H15: 13 | I15: 4.5516667 | J15: 43483 | K15: 已完结 | L15: 24.5
A16: =ROW()-2 -> 14 | B16: 有声书 | C16: 财经 | D16: 灰犀牛：如何应对大概率危机 | E16: 米歇尔·渥克 | F16: 中信书院 | G16: 全员 | H16: 63 | I16: 32.301667 | J16: 43483 | K16: 已完结 | L16: 24.5
A17: =ROW()-2 -> 15 | B17: 有声书 | C17: 财经 | D17: 滚雪球：巴菲特和他的财富人生(下) | E17: 艾丽斯·施罗德 | F17: 中信书院 | G17: 全员 | H17: 22 | I17: 7.5147222 | J17: 43483 | K17: 已完结 | L17: 29.99
... A40: =ROW()-2 -> 38 | B40: 有声书 | C40: 财经 | D40: 财报思维 | E40: 王峰 | F40: 旧时烟 | G40: 全员 | H40: 143 | I40: 15.295 | J40: 44566 | K40: 已完结 | L40: 49.99
A41: =ROW()-2 -> 39 | B41: 有声书 | C41: 财经 | D41: 世界是部金融史 | E41: 陈雨露 | F41: 索析文化 | G41: 全员 | H41: 95 | I41: 15.151667 | J41: 44566 | K41: 已完结
A42: =ROW()-2 -> 40 | B42: 有声书 | C42: 财经 | D42: 读懂双循环新发展格局 | E42: 刘元春 | F42: 中信书院 | G42: 全员 | H42: 29 | I42: 4.8 | J42: 44585 | K42: 已完结 | L42: 34
A43: =ROW()-2 -> 41 | B43: 有声书 | C43: 财经 | D43: 一套书弄懂全球经济命脉 | E43: 赵伟、胡晓磊 | F43: 何建军 | G43: 全员 | H43: 176 | I43: 35.2 | J43: 44599 | K43: 已完结 | L43: 59.99
A44: =ROW()-2 -> 42 | B44: 有声书 | C44: 财经 | D44: 读懂未来中国经济：”十四五“到2035 | E44: ​蔡昉 | F44: 中信书院 | G44: 全员 | H44: 54 | I44: 10.395278 | J44: 44614 | K44: 已完结 | L44: 34.5
A45: =ROW()-2 -> 43 | B45: 有声书 | C45: 财经 | D45: 一本书读懂财务报表 | E45: 文杨 | F45: 流星星 | G45: 全员 | H45: 32 | I45: 5.4488889 | J45: 44614 | K45: 已完结 | L45: 19.99
A46: =ROW()-2 -> 44 | B46: 有声书 | C46: 创业 | D46: 小米生态链战地笔记 | E46: 小米生态链谷仓学院 | F46: 中信书院 | G46: 全员 | H46: 17 | I46: 4.6116667 | J46: 43468 | K46: 已完结 | L46: 59.99
A47: =ROW()-2 -> 45 | B47: 有声书 | C47: 创业 | D47: 华为教父任正非 | E47: 刘世英，彭征明 | F47: kting北京东方视角 | G47: 全员 | H47: 32 | I47: 10.848056 | J47: 43469 | K47: 已完结 | L47: 39.99
A48: =ROW()-2 -> 46 | B48: 有声书 | C48: 创业 | D48: 创业无畏 | E48: 彼得·戴曼迪斯，史蒂芬·科特勒 | F48: 湛庐阅读 | G48: 全员 | H48: 30 | I48: 8.9858333 | J48: 43469 | K48: 已完结 | L48: 49
A49: =ROW()-2 -> 47 | B49: 有声书 | C49: 创业 | D49: 投资异类 | E49: 王利杰 | F49: 湛庐阅读 | G49: 全员 | H49: 78 | I49: 13.182222 | J49: 43469 | K49: 已完结 | L49: 24.5
A50: =ROW()-2 -> 48 | B50: 有声书 | C50: 创业 | D50: 从0到1:开启商业与未来的秘密 | E50: 彼得·蒂尔，布莱克·马斯特斯 | F50: 中信书院 | G50: 全员 | H50: 37 | I50: 15.908611 | J50: 43469 | K50: 已完结 | L50: 8.99
A51: =ROW()-2 -> 49 | B51: 有声书 | C51: 创业 | D51: 精益创业 | E51: 埃里克.莱斯 | F51: 中信书院 | G51: 全员 | H51: 20 | I51: 2.5325 | J51: 43483 | K51: 已完结 | L51: 22.5
A52: =ROW()-2 -> 50 | B52: 有声书 | C52: 创业 | D52: 创业合伙人实战课 | E52: 武帅 | F52: 中信书院 | G52: 全员 | H52: 24 | I52: 8.3763889 | J52: 43483 | K52: 已完结 | L52: 9.9
A53: =ROW()-2 -> 51 | B53: 有声书 | C53: 创业 | D53: 鞋狗 | E53: 菲尔·奈特 | F53: 湛庐阅读 | G53: 全员 | H53: 15 | I53: 5.7608333 | J53: 43691 | K53: 已完结 | L53: 34.5
... A88: =ROW()-2 -> 86 | B88: 有声书 | C88: 管理 | D88: 数字化转型方法论 | E88: 马晓东 | F88: 马晓东 | G88: 全员 | H88: 38 | I88: 12 | J88: 44390 | K88: 已完结 | L88: 49.9
A89: =ROW()-2 -> 87 | B89: 有声书 | C89: 管理 | D89: 稻盛和夫：企业经营实战系列合集 | E89: 稻盛和夫 | F89: HE北笙 | G89: 全员 | H89: 137 | I89: 18.596667 | J89: 44614 | K89: 已完结
A90: =ROW()-2 -> 88 | B90: 有声书 | C90: 管理 | D90: 竞争战略 | E90: 迈克尔·波特 | F90: 中信书院 | G90: 全员 | H90: 37 | I90: 15.389444 | J90: 44614 | K90: 未完结 | L90: 44
A91: =ROW()-2 -> 89 | B91: 有声书 | C91: 管理 | D91: 创新型组织：构建组织可持续的创新力 | E91: 薛旭亮 | G91: 全员 | H91: 44 | I91: 6.7505556 | J91: 44614 | K91: 已完结 | L91: 33.9
A92: =ROW()-2 -> 90 | B92: 有声书 | C92: 管理 | D92: 赋能 | E92: 斯坦利·麦克里斯特尔 | F92: 中信书院 | G92: 全员 | H92: 34 | I92: 12.6275 | J92: 44614 | K92: 未完结 | L92: 24.5
A93: =ROW()-2 -> 91 | B93: 有声书 | C93: 管理 | D93: 增长结构 | E93: 王赛 | F93: 中信书院 | G93: 全员 | H93: 58 | I93: 9.9238889 | J93: 44614 | K93: 已完结 | L93: 34
A94: =ROW()-2 -> 92 | B94: 有声书 | C94: 管理 | D94: 德鲁克的管理秘诀 | E94: 郑一群 | F94: 梦语阁文化传媒 | G94: 全员 | H94: 37 | I94: 12.129167 | J94: 44614 | K94: 已完结 | L94: 14.99
A95: =ROW()-2 -> 93 | B95: 有声书 | C95: 管理 | D95: 600位富商的经营之道 | E95: 张俊杰 | F95: 天下书盟精品图书 | G95: 全员 | H95: 171 | I95: 24.944167 | J95: 44614 | K95: 已完结 | L95: 56.88
A96: =ROW()-2 -> 94 | B96: 有声书 | C96: 管理 | D96: 逆势增长的商业模式 | E96: 石泽杰 | F96: 电子工业出版社 | G96: 全员 | H96: 33 | I96: 8.0291667 | J96: 44614 | K96: 已完结 | L96: 39
...

Sheet 讲书
A1: 讲书
A2: 序号 | B2: 书籍大类 | C2: 分类 | D2: 书籍名称 | E2: 作者 | F2: 主讲人 | G2: 适听人群 | H2: 集数 | I2: 已上架课时总时间/h | J2: 轻学堂上架日期 | K2: 更新状态 | L2: 单卖价格/元
A3: =ROW()-2 -> 1 | B3: 讲书 | C3: 财经 | D3: 文明寻思录 | E3: 秦朔 | F3: 秦朔 | G3: 全员 | H3: 1 | I3: 0.63472222 | J3: 43468 | K3: 已完结 | L3: 4.99
A4: =ROW()-2 -> 2 | B4: 讲书 | C4: 财经 | D4: 经营分析与估值 | E4: 克雷沙·G·帕利普 | F4: 薛云奎 | G4: 全员 | H4: 1 | I4: 0.54777778 | J4: 43469 | K4: 已完结 | L4: 4.99
A5: =ROW()-2 -> 3 | B5: 讲书 | C5: 财经 | D5: 华尔街幽灵 | E5: 阿瑟·L·辛普森 | F5: 孟可 | G5: 全员 | H5: 1 | I5: 0.71916667 | J5: 43469 | K5: 已完结 | L5: 4.99
A6: =ROW()-2 -> 4 | B6: 讲书 | C6: 财经 | D6: 魔鬼经济学 | E6: 史蒂芬·列维特/史蒂芬·都伯纳 | F6: 元生 | G6: 全员 | H6: 1 | I6: 0.75722222 | J6: 43469 | K6: 已完结 | L6: 4.99
A7: =ROW()-2 -> 5 | B7: 讲书 | C7: 财经 | D7: 不平等的代价 | E7: 约瑟夫·E·斯蒂格利茨 | F7: 李长安 | G7: 全员 | H7: 1 | I7: 0.49472222 | J7: 43483 | K7: 已完结 | L7: 4.99
A8: =ROW()-2 -> 6 | B8: 讲书 | C8: 财经 | D8: 新财富管理 | E8: 哈罗德·埃文斯基，斯蒂芬·M·霍伦，托马斯·R·罗宾逊 | F8: 李清昊 | G8: 全员 | H8: 29 | I8: 8.8205556 | J8: 43483 | K8: 已完结 | L8: 4.99
A9: =ROW()-2 -> 7 | B9: 讲书 | C9: 财经 | D9: 1844年经济学哲学手稿 | E9: 卡尔·马克思 | F9: 薛晓明 | G9: 全员 | H9: 1 | I9: 0.40611111 | J9: 43962 | K9: 已完结 | L9: 4.99
A10: =ROW()-2 -> 8 | B10: 讲书 | C10: 财经 | D10: 游戏改变世界 | E10: 简·麦戈尼格尔 | F10: 英国报姐 | G10: 全员 | H10: 1 | I10: 0.35777778 | J10: 43962 | K10: 已完结 | L10: 4.99
A11: =ROW()-2 -> 9 | B11: 讲书 | C11: 财经 | D11: 爆裂 | E11: 伊藤穰一，杰夫·豪 | F11: 曹易伦 | G11: 全员 | H11: 1 | I11: 0.45055556 | J11: 43962 | K11: 已完结 | L11: 4.99
A12: =ROW()-2 -> 10 | B12: 讲书 | C12: 财经 | D12: 逃不开的经济周期 | E12: 拉斯·特维德 | F12: 魏强斌 | G12: 全员 | H12: 1 | I12: 0.42055556 | J12: 43962 | K12: 已完结 | L12: 4.99
A13: =ROW()-2 -> 11 | B13: 讲书 | C13: 财经 | D13: 行动的勇气 | E13: 本·伯南克 | F13: 李长安 | G13: 全员 | H13: 1 | I13: 0.46555556 | J13: 43962 | K13: 已完结 | L13: 4.99
A14: =ROW()-2 -> 12 | B14: 讲书 | C14: 财经 | D14: 引爆点 | E14: 马尔科姆·格拉德威尔 | F14: 耿人健 | G14: 全员 | H14: 1 | I14: 0.30138889 | J14: 43962 | K14: 已完结 | L14: 4.99
... A129: =ROW()-2 -> 127 | B129: 讲书 | C129: 财经 | D129: 极简法则 | E129: 理查德·科克 | F129: 西蒙 | G129: 全员 | H129: 1 | I129: 0.52 | J129: 44186 | K129: 已完结 | L129: 4.99
A130: =ROW()-2 -> 128 | B130: 讲书 | C130: 财经 | D130: 未来银行 | E130: 乔纳森·马米兰 | F130: 刘美 | G130: 全员 | H130: 1 | I130: 0.5 | J130: 44263 | K130: 已完结 | L130: 4..99
A131: =ROW()-2 -> 129 | B131: 讲书 | C131: 财经 | D131: 财富的起源 | E131: 埃里克·拜因霍克 | F131: 章永宏 | G131: 全员 | H131: 1 | I131: 0.5 | J131: 44522 | K131: 已完结 | L131: 4..99
A132: =ROW()-2 -> 130 | B132: 讲书 | C132: 财经 | D132: 中间人经济 | E132: 玛丽娜·克拉科夫斯基 | F132: 陈曦 | G132: 全员 | H132: 1 | I132: 0.5 | J132: 44543 | K132: 已完结 | L132: 4..99
A133: =ROW()-2 -> 131 | B133: 讲书 | C133: 财经 | D133: 一本书读懂财报 | E133: 肖星 | F133: 刘美 | G133: 全员 | H133: 1 | I133: 0.49 | J133: 44551 | K133: 已完结 | L133: 4.99
A134: =ROW()-2 -> 132 | B134: 讲书 | C134: 财经 | D134: 与运气竞争 | E134: 克莱顿·克里斯坦森 | F134: 陈曦 | G134: 全员 | H134: 1 | I134: 0.48 | J134: 44578 | K134: 已完结 | L134: 4..100
A135: =ROW()-2 -> 133 | B135: 讲书 | C135: 财经 | D135: 价值 | E135: 张磊 | F135: 武京丽 | G135: 全员 | H135: 1 | I135: 0.5 | J135: 44620 | K135: 已完结 | L135: 4.9
A136: =ROW()-2 -> 134 | B136: 讲书 | C136: 创业 | D136: 一胜九败：优衣库风靡全球的秘密 | E136: 柳井正 | F136: 徐静波 | G136: 全员 | H136: 1 | I136: 0.52888889 | J136: 43469 | K136: 已完结 | L136: 4.99
A137: =ROW()-2 -> 135 | B137: 讲书 | C137: 创业 | D137: 创新公司 | E137: 艾德·卡特姆/埃米·华莱士 | F137: 图南 | G137: 全员 | H137: 1 | I137: 0.46666667 | J137: 43962 | K137: 已完结 | L137: 4.99
A138: =ROW()-2 -> 136 | B138: 讲书 | C138: 创业 | D138: 疯传 | E138: 乔纳·伯杰 | F138: 周华明 | G138: 全员 | H138: 1 | I138: 0.73194444 | J138: 43962 | K138: 已完结 | L138: 4.99
A139: =ROW()-2 -> 137 | B139: 讲书 | C139: 创业 | D139: 一网打尽 | E139: 布拉德·斯通 | F139: 陈聪明 | G139: 全员 | H139: 1 | I139: 0.42777778 | J139: 43978 | K139: 已完结 | L139: 4.99
A140: =ROW()-2 -> 138 | B140: 讲书 | C140: 创业 | D140: 鞋狗 | E140: 菲尔·奈特 | F140: 邹大湿 | G140: 全员 | H140: 1 | I140: 0.56611111 | J140: 43978 | K140: 已完结 | L140: 4.99
A141: =ROW()-2 -> 139 | B141: 讲书 | C141: 创业 | D141: 孙正义：未来的机遇在哪里 | E141: 井上笃夫 | F141: 钱老师 | G141: 全员 | H141: 1 | I141: 1.9375 | J141: 43978 | K141: 已完结 | L141: 4.99
A142: =ROW()-2 -> 140 | B142: 讲书 | C142: 创业 | D142: 从0到1 | E142: 彼得·蒂尔 | F142: 沈攀 | G142: 全员 | H142: 1 | I142: 0.79277778 | J142: 43978 | K142: 已完结 | L142: 4.99
A143: =ROW()-2 -> 141 | B143: 讲书 | C143: 创业 | D143: 重新定义公司:谷歌是如何运营的 | E143: 埃里克·施密特/乔纳森·罗森伯格 | F143: 沈攀 | G143: 全员 | H143: 1 | I143: 0.4175 | J143: 43978 | K143: 已完结 | L143: 4.99
A144: =ROW()-2 -> 142 | B144: 讲书 | C144: 创业 | D144: Facebook效应 | E144: 大卫·柯克帕特里克 | F144: 韩春苗 | G144: 全员 | H144: 1 | I144: 0.55444444 | J144: 43978 | K144: 已完结 | L144: 4.99
A145: =ROW()-2 -> 143 | B145: 讲书 | C145: 创业 | D145: 硅谷钢铁侠 | E145: 阿什利·万斯 | F145: 高融 | G145: 全员 | H145: 1 | I145: 0.3075 | J145: 43978 | K145: 已完结 | L145: 4.99
A146: =ROW()-2 -> 144 | B146: 讲书 | C146: 创业 | D146: 单点突破 | E146: 张本伟/赵鑫 /杨琰华 | F146: 施襄 | G146: 全员 | H146: 1 | I146: 0.43944444 | J146: 43978 | K146: 已完结 | L146: 4.99
... A160: =ROW()-2 -> 158 | B160: 讲书 | C160: 创业 | D160: 微创新 | E160: 雅各布·哥登堡 | F160: 严智砾 | G160: 全员 | H160: 1 | I160: 0.4 | J160: 44102 | K160: 已完结 | L160: 4.99
A161: =ROW()-2 -> 159 | B161: 讲书 | C161: 创业 | D161: 翻转课堂的可汗学院 | E161: 萨尔曼·可汗 | F161: 陈曦 | G161: 全员 | H161: 1 | I161: 0.36 | J161: 44123 | K161: 已完结 | L161: 4..99
A162: =ROW()-2 -> 160 | B162: 讲书 | C162: 创业 | D162: 事实（上） | E162: 汉斯·罗斯林 | F162: 林伯虎 | G162: 全员 | H162: 1 | I162: 0.49555556 | J162: 44158 | K162: 已完结 | L162: 4.99
A163: =ROW()-2 -> 161 | B163: 讲书 | C163: 创业 | D163: 富甲美国 | E163: 山姆·沃尔顿 | F163: 果真 | G163: 全员 | H163: 1 | I163: 0.4 | J163: 44529 | K163: 已完结 | L163: 4.99
A164: =ROW()-2 -> 162 | B164: 讲书 | C164: 管理 | D164: 罗伯特议事规则 | E164: 亨利·罗伯特 | F164: 图南 | G164: 全员 | H164: 1 | I164: 0.36666667 | J164: 43468 | K164: 已完结 | L164: 4.99
A165: =ROW()-2 -> 163 | B165: 讲书 | C165: 管理 | D165: 驱动力 | E165: 丹尼尔·平克 | F165: 元生 | G165: 全员 | H165: 1 | I165: 0.405 | J165: 43468 | K165: 已完结 | L165: 4.99
A166: =ROW()-2 -> 164 | B166: 讲书 | C166: 管理 | D166: 商业的本质 | E166: 杰克·韦尔奇，苏茜·韦尔奇 | F166: 曾言 | G166: 全员 | H166: 1 | I166: 0.50305556 | J166: 43469 | K166: 已完结 | L166: 4.99
A167: =ROW()-2 -> 165 | B167: 讲书 | C167: 管理 | D167: 第五项修炼 | E167: 彼得·圣吉 | F167: 刘杰辉 | G167: 全员 | H167: 1 | I167: 0.70555556 | J167: 43469 | K167: 已完结 | L167: 4.99
...
