Workbook

Sheet 利润表
A1: 利润表
A2: 西安赛格 | B2: 45869 | E2: 单位：元
A3: 项 目 | B3: 本期金额 | C3: 本期占比流水 | D3: 本期占比净收 | E3: 本年累计金额 | F3: 本年占比流水 | G3: 本年占比净收
A4: 一、主营业务数据
A5: 1、主营业务收入 | B5: 870370.9 | C5: 1 | E5: 4753310.8 | F5: 1
A6: (1)、烘焙收入 | B6: 693886.4 | C6: 0.8 | E6: 3707259.3 | F6: 0.78
A7: (2)、三明治收入 | B7: 0 | C7: 0 | E7: 0 | F7: 0
A8: (3)、水吧收入 | B8: 0 | C8: 0 | E8: 0 | F8: 0
A9: (4)、果酱收入 | B9: 0 | C9: 0 | E9: 0 | F9: 0
A10: (5)、西点收入 | B10: 174033 | C10: 0.2 | E10: 1043600 | F10: 0.22
A11: (6)、商品收入 | B11: 2451.5 | C11: 0 | E11: 2451.5 | F11: 0
A12: 2、销售折扣折让 | B12: 101754.79 | C12: 0.12 | E12: 584178 | F12: 0.12
A13: (1)、烘焙折扣折让 | B13: 91348.98 | C13: 0.13 | E13: 492622.87 | F13: 0.13
A14: (2)、三明治折扣折让 | B14: 0 | C14: #DIV/0! | E14: 0 | F14: #DIV/0!
A15: (3)、水吧折扣折让 | B15: 0 | C15: #DIV/0! | E15: 0 | F15: #DIV/0!
A16: (4)、果酱折扣折让 | B16: 0 | C16: #DIV/0! | E16: 0 | F16: #DIV/0!
A17: (5)、西点折扣折让 | B17: 9830.89 | C17: 0.06 | E17: 90980.21 | F17: 0.09
A18: (6)、商品折扣折让 | B18: 574.92 | C18: 0.23 | E18: 574.92 | F18: 0.23
A19: 3、销售试吃 | B19: 34714 | C19: 0.04 | E19: 200127.97 | F19: 0.04
A20: (1)、烘焙试吃 | B20: 33495 | C20: 0.05 | E20: 194586.62 | F20: 0.05
A21: (2)、三明治试吃 | B21: 0 | C21: #DIV/0! | E21: 0 | F21: #DIV/0!
A22: (3)、水吧试吃 | B22: 0 | C22: #DIV/0! | E22: 0 | F22: #DIV/0!
A23: (4)、果酱试吃 | B23: 0 | C23: #DIV/0! | E23: 0 | F23: #DIV/0!
A24: (5)、西点试吃 | B24: 1219 | C24: 0.01 | E24: 5541.35 | F24: 0.01
A25: (6)、商品试吃 | B25: 0 | C25: 0 | E25: 0 | F25: 0
A26: 4、销售报损 | B26: 19595 | C26: 0.02 | E26: 147755 | F26: 0.03
A27: (1)、烘焙报损 | B27: 19559 | C27: 0.03 | E27: 145492 | F27: 0.04
A28: (2)、三明治报损 | B28: 0 | C28: #DIV/0! | E28: 0 | F28: #DIV/0!
A29: (3)、水吧报损 | B29: 0 | C29: #DIV/0! | E29: 0 | F29: #DIV/0!
A30: (4)、果酱报损 | B30: 0 | C30: #DIV/0! | E30: 0 | F30: #DIV/0!
A31: (5)、西点报损 | B31: 36 | C31: 0 | E31: 2263 | F31: 0
A32: (6)、商品报损 | B32: 0 | C32: 0 | E32: 0 | F32: 0
A33: 5、主营业务净收入 | B33: 714307.11 | C33: 0.82 | D33: 1 | E33: 3821249.8 | F33: 0.8 | G33: 1
A34: (1)、烘焙净收入 | B34: 549483.42 | C34: 0.79 | D34: 0.77 | E34: 2874557.8 | F34: 0.78 | G34: 0.75
A35: (2)、三明治净收入 | B35: 0 | C35: #DIV/0! | D35: 0 | E35: 0 | F35: #DIV/0! | G35: 0
A36: (3)、水吧净收入 | B36: 0 | C36: #DIV/0! | D36: 0 | E36: 0 | F36: #DIV/0! | G36: 0
A37: (4)、果酱净收入 | B37: 0 | C37: #DIV/0! | D37: 0 | E37: 0 | F37: #DIV/0! | G37: 0
A38: (5)、西点净收入 | B38: 162947.11 | C38: 0.94 | D38: 0.23 | E38: 944815.44 | F38: 0.91 | G38: 0.25
A39: (6)、商品净收入 | B39: 1876.58 | C39: 0.77 | D39: 0 | E39: 1876.58 | F39: 0.77 | G39: 0
A40: 6、减：主营业务成本 | B40: 271880.72 | C40: 0.31 | D40: 0.38 | E40: 1498220.3 | F40: 0.32 | G40: 0.39
...

Sheet 资产负债表
A1: 资产负债表
F2: 会企01表
A3: 编制单位：西安赛格 | D3: 45869 | F3: 单位：元
A4: 资产 | B4: 期末余额 | C4: 上年年末余额 | D4: 负债和所有者权益（或股东权益） | E4: 期末余额 | F4: 上年年末余额
A5: 流动资产: | D5: 流动负债:
A6: 货币资金 | B6: 491477.16 | C6: 0 | D6: 短期借款 | E6: 0 | F6: 0
A7: 以公允价值计量且其变动计入当期损益的金融资产 | B7: 0 | C7: 0 | D7: 以公允价值计量且其变动计入当期损益的金融负债 | E7: 0 | F7: 0
A8: 衍生金融资产 | B8: 0 | C8: 0 | D8: 衍生金融负债 | E8: 0 | F8: 0
A9: 应收票据 | B9: 0 | C9: 0 | D9: 应付票据 | E9: 0 | F9: 0
A10: 应收账款 | B10: 83686.43 | C10: 0 | D10: 应付账款 | E10: 61912.29 | F10: 0
A11: 预付款项 | B11: 241371.45 | C11: 0 | D11: 预收款项 | E11: 120944.61 | F11: 0
A12: 其他应收款 | B12: 7126.85 | C12: 0 | D12: 应付职工薪酬 | E12: 165741.65 | F12: 0
A13: 存货 | B13: 269867.51 | C13: 0 | D13: 应交税费 | E13: 0 | F13: 0
A14: 持有待售资产 | B14: 0 | C14: 0 | D14: 其他应付款 | E14: 18632.99 | F14: 0
A15: 一年内到期的非流动资产 | D15: 持有待售负债 | E15: 0 | F15: 0
A16: 其他流动资产 | B16: 0 | C16: 0 | D16: 一年内到期的非流动负债
D17: 其他流动负债 | E17: 0 | F17: 0
A18: 流动资产合计 | B18: 1093529.4 | C18: 0 | D18: 流动负债合计 | E18: 367231.54 | F18: 0
A19: 非流动资产: | D19: 非流动负债:
A20: 可供出售金融资产 | B20: 0 | C20: 0 | D20: 长期借款 | E20: 0 | F20: 0
A21: 持有至到期投资 | B21: 0 | C21: 0 | D21: 应付债券 | E21: 0 | F21: 0
A22: 长期应收款 | B22: 0 | C22: 0 | D22: 其中：优先股
A23: 长期股权投资 | B23: 0 | C23: 0 | D23: 永续债
A24: 投资性房地产 | B24: 0 | C24: 0 | D24: 长期应付款 | E24: 0 | F24: 0
A25: 固定资产 | B25: 438898.36 | C25: 0 | D25: 预计负债 | E25: 0 | F25: 0
A26: 在建工程 | B26: 0 | C26: 0 | D26: 递延收益 | E26: 0 | F26: 0
A27: 生产性生物资产 | B27: 0 | C27: 0 | D27: 递延所得税负债 | E27: 0 | F27: 0
A28: 油气资产 | B28: 0 | C28: 0 | D28: 其他非流动负债
A29: 无形资产 | B29: 19259.41 | C29: 0 | D29: 非流动负债合计 | E29: 0 | F29: 0
A30: 开发支出 | B30: 0 | C30: 0 | D30: 负债合计 | E30: 367231.54 | F30: 0
A31: 商誉 | B31: 0 | C31: 0 | D31: 所有者权益（或股东权益）:
A32: 长期待摊费用 | B32: 836817.44 | C32: 0 | D32: 实收资本(股本) | E32: 2018110.7 | F32: 0
A33: 递延所得税资产 | B33: 0 | C33: 0 | D33: 其他权益工具 | E33: 0 | F33: 0
A34: 其他非流动资产 | B34: 0 | C34: 0 | D34: 其中：优先股
A35: 非流动资产合计 | B35: 1294975.2 | C35: 0 | D35: 永续债
D36: 资本公积 | E36: 0 | F36: 0
D37: 减:库存股 | E37: 0 | F37: 0
D38: 其他综合收益 | E38: 0 | F38: 0
D39: 专项储备 | E39: 0 | F39: 0
D40: 盈余公积 | E40: 0 | F40: 0
...

Sheet 现金流量表
A1: 账簿:西安赛格 | B1: 币别:人民币 | C1: 查询范围:2025.7 -- 2025.7
A2: 项目类别 | B2: 现金流量项目 | C2: 行次 | D2: 金额
A3: 1 | B3: 经营活动产生的现金流量
B4: 销售商品、提供劳务收到的现金 | C4: 1 | D4: 705948.7
B5: 收到的税费返还 | C5: 2
B6: 收到其他与经营活动有关的现金 | C6: 3 | D6: 10987.26
B7: 现金流入小计 | C7: 4 | D7: 716935.96
B8: 购买商品、接受劳务支付的现金 | C8: 5 | D8: 276390.85
B9: 支付给职工以及为职工支付的现金 | C9: 6 | D9: 158336.8
B10: 支付的各项税费 | C10: 7 | D10: 11541.51
B11: 支付其他与经营活动有关的现金 | C11: 8 | D11: 85647.91
B12: 现金流出小计 | C12: 9 | D12: 531917.07
B13: 经营活动产生的现金流量净额 | C13: 10 | D13: 185018.89
A14: 2 | B14: 投资活动产生的现金流量
B15: 收回投资收到的现金 | C15: 11
B16: 取得投资收益收到的现金 | C16: 12
B17: 处置固定资产、无形资产和其他长期资产收回的现金净额 | C17: 13
B18: 处置子公司及其他营业单位收到的现金净额 | C18: 14
B19: 收到其他与投资活动有关的现金 | C19: 15
B20: 现金流入小计 | C20: 16
B21: 购建固定资产、无形资产和其他长期资产支付的现金 | C21: 17
B22: 投资支付的现金 | C22: 18
B23: 取得子公司及其他营业单位支付的现金净额 | C23: 19
B24: 支付其他与投资活动有关的现金 | C24: 20
B25: 现金流出小计 | C25: 21
B26: 投资活动产生的现金流量净额 | C26: 22
A27: 3 | B27: 筹资活动产生的现金流量
B28: 吸收投资收到的现金 | C28: 23
B29: 取得借款收到的现金 | C29: 24
B30: 收到其他与筹资活动有关的现金 | C30: 25
B31: 现金流入小计 | C31: 26
B32: 偿还债务支付的现金 | C32: 27
B33: 分配股利、利润或偿付利息支付的现金 | C33: 28 | D33: 30751.9
B34: 支付其他与筹资活动有关的现金 | C34: 29
B35: 现金流出小计 | C35: 30 | D35: 30751.9
B36: 筹资活动产生的现金流量净额 | C36: 31 | D36: -30751.9
A37: 4 | B37: 汇率变动对现金及现金等价物的影响 | C37: 35
A38: 5 | B38: 现金及现金等价物净增加额 | C38: 36 | D38: 154266.99
B39: 加：期初现金及现金等价物余额 | C39: 37 | D39: 337210.17
A40: 6 | B40: 期末现金及现金等价物余额 | C40: 38 | D40: 491477.16
...

Sheet 资产负债表附表
A1: 资产负债表科目 | B1: 资产负债表余额 | C1: 科目名称 | D1: 期初借方余额 | E1: 期初贷方余额 | F1: 本期借方发生额 | G1: 本期贷方发生额 | H1: 期末借方余额 | I1: 期末贷方余额 | J1: 备注说明 | K1: 校验
A2: 货币资金 | B2: =资产负债表!B6 -> 491477.16 | C2: 库存现金 | D2: 12890.78 | F2: 10508.5 | G2: 19992.28 | H2: 3407 | K2: =B2-SUM(H2:H3) -> 0
C3: 银行存款 | D3: 324319.39 | F3: 1053005.1 | G3: 889254.34 | H3: 488070.16
A4: 应收账款 | B4: =资产负债表!B10 -> 83686.43 | C4: [001]美团团购 | D4: 21544.26 | F4: 114816.55 | G4: 104527.4 | H4: 31833.41 | K4: =B4-SUM(H4:H12) -> 0
C5: [002]美团外卖 | D5: 1920.95 | F5: 11166.7 | G5: 12136.86 | H5: 950.79
C6: [003]饿了么外卖 | D6: 1737.07 | F6: 17663.97 | G6: 17996.46 | H6: 1404.58
C7: [004]抖音团购 | D7: 13877.94 | F7: 62503.66 | G7: 68363.91 | H7: 8017.69
C8: [005]云纵商家-微信支付宝 | D8: 17475.35 | F8: 493614.31 | G8: 497897.08 | H8: 13192.58
C9: [006]交通银行
C10: [007]招商银行 | F10: 4108.5 | G10: 3667 | H10: 441.5
C11: [008]京东外卖 | D11: 204.41 | F11: 1364.81 | G11: 1359.99 | H11: 209.23
C12: [009]万象卡 | D12: 21742.49 | F12: 5894.16 | H12: 27636.65
C13: [013]招商银行
A14: =资产负债表!A11 -> 预付款项 | B14: =资产负债表!B11 -> 241371.45 | C14: 预付库房租金 | D14: 388611.45 | G14: 147240 | H14: 241371.45 | J14: 预付库房租金 | K14: =B14-H14 -> 0
A15: 其他应收款 | B15: =资产负债表!B12 -> 7126.85 | C15: 员工往来 | D15: 9000 | H15: 9000 | J15: 1、开办投入中用于预付当期费用部分2、员工借款。以上计入员工往来 | K15: =B15-(H15+H16+H37+H45+H46+H47-I15-I16-I37-I45-I46-I47) -> -3.4560799e-11
C16: 公司往来 | E16: 284587.72 | F16: 51612.96 | G16: 34606.15 | I16: 267580.91 | J16: 公司之间应收应付往来款，计入公司往来
C17: 管理公司 | E17: 174893.17 | F17: 47492.2 | G17: 28825.81 | I17: 156226.78 | J17: 应付管理费
C18: 沈阳崎本 | J18: 公司之间应收应付往来款，计入公司往来
C19: 长春崎本 | E19: 40000 | I19: 40000 | J19: 公司之间应收应付往来款，计入公司往来
C20: 青岛崎本
C21: 南京崎本 | J21: 公司之间应收应付往来款，计入公司往来
C22: 成都崎本 | E22: 1332.32 | I22: 1332.32 | J22: 公司之间应收应付往来款，计入公司往来
C23: 海南蕊礼贸易有限公司 | E23: 50000 | I23: 50000 | J23: 公司之间应收应付往来款，计入公司往来
C24: 崎本-北京荟聚店
C25: 崎本-北京清河万象汇
C26: 崎本-珠海优特汇
C27: 沈阳乐姿网络传媒有限公司 | E27: 6087.03 | G27: 3821.58 | I27: 9908.61
C28: 崎本-大连高新 | D28: 358.5 | H28: 358.5
C29: 山亩-天津万象城 | E29: 3200 | G29: 1480 | I29: 4680
C30: 膨胀团-沈阳环宇城店
C31: 崎本-北京龙湖丽泽店 | E31: 12375.7 | I31: 12375.7
C32: 崎本-杭州万象城 | E32: 1480 | I32: 1480
C33: 崎本-郑州正弘城 | D33: 4422 | F33: 4120.76 | G33: 478.76 | H33: 8064
C37: 押金/保证金 | D37: 255640 | H37: 255640
C38: 租赁保证金 | D38: 241040 | H38: 241040
C39: 水电费押金 | D39: 1600 | H39: 1600
C40: 寝室押金 | D40: 6900 | H40: 6900
C41: 仓库押金 | D41: 4100 | H41: 4100
C42: 其他押金 | D42: 2000 | H42: 2000
C45: 代扣员工个人保险 | D45: 3869.09 | F45: 12002.31 | G45: 5803.64 | H45: 10067.76 | J45: 代扣员工个人保险
...
